nohup: ignoring input
[2024-10-22 09:50:56] [INFO    ] discord.client: logging in using static token
[2024-10-22 09:50:57] [INFO    ] discord.gateway: Shard ID None has connected to Gateway (Session ID: 239f88344c078ca8ffa403aa21628bdb).
[2024-10-22 10:35:09] [INFO    ] discord.gateway: Shard ID None has successfully RESUMED session 239f88344c078ca8ffa403aa21628bdb.
[2024-10-22 12:20:12] [INFO    ] discord.gateway: Shard ID None has successfully RESUMED session 239f88344c078ca8ffa403aa21628bdb.
[2024-10-22 16:10:43] [INFO    ] discord.gateway: Shard ID None has successfully RESUMED session 239f88344c078ca8ffa403aa21628bdb.
[2024-10-22 16:19:08] [INFO    ] discord.gateway: Shard ID None has successfully RESUMED session 239f88344c078ca8ffa403aa21628bdb.
[2024-10-22 18:54:31] [INFO    ] discord.gateway: Shard ID None has successfully RESUMED session 239f88344c078ca8ffa403aa21628bdb.
[2024-10-22 19:15:37] [INFO    ] discord.gateway: Shard ID None has successfully RESUMED session 239f88344c078ca8ffa403aa21628bdb.
[2024-10-22 19:39:54] [INFO    ] discord.gateway: Shard ID None has successfully RESUMED session 239f88344c078ca8ffa403aa21628bdb.
[2024-10-22 22:05:16] [INFO    ] discord.gateway: Shard ID None has successfully RESUMED session 239f88344c078ca8ffa403aa21628bdb.
[2024-10-23 01:44:40] [INFO    ] discord.gateway: Shard ID None has successfully RESUMED session 239f88344c078ca8ffa403aa21628bdb.
[2024-10-23 03:32:55] [INFO    ] discord.gateway: Shard ID None has successfully RESUMED session 239f88344c078ca8ffa403aa21628bdb.
[2024-10-23 06:32:15] [INFO    ] discord.gateway: Shard ID None has successfully RESUMED session 239f88344c078ca8ffa403aa21628bdb.
[2024-10-23 06:57:34] [INFO    ] discord.gateway: Shard ID None has successfully RESUMED session 239f88344c078ca8ffa403aa21628bdb.
[2024-10-23 07:49:30] [INFO    ] discord.gateway: Shard ID None has successfully RESUMED session 239f88344c078ca8ffa403aa21628bdb.
[2024-10-23 11:09:42] [INFO    ] discord.gateway: Shard ID None has successfully RESUMED session 239f88344c078ca8ffa403aa21628bdb.
[2024-10-23 11:52:05] [INFO    ] discord.gateway: Shard ID None has successfully RESUMED session 239f88344c078ca8ffa403aa21628bdb.
[2024-10-23 12:17:21] [INFO    ] discord.gateway: Shard ID None has successfully RESUMED session 239f88344c078ca8ffa403aa21628bdb.
[2024-10-23 13:10:03] [INFO    ] discord.gateway: Shard ID None has successfully RESUMED session 239f88344c078ca8ffa403aa21628bdb.
[2024-10-23 15:01:26] [INFO    ] discord.gateway: Shard ID None has successfully RESUMED session 239f88344c078ca8ffa403aa21628bdb.
[2024-10-23 15:35:49] [INFO    ] discord.gateway: Shard ID None has successfully RESUMED session 239f88344c078ca8ffa403aa21628bdb.
[2024-10-23 18:55:01] [INFO    ] discord.gateway: Shard ID None has successfully RESUMED session 239f88344c078ca8ffa403aa21628bdb.
[2024-10-23 20:15:58] [INFO    ] discord.gateway: Shard ID None has successfully RESUMED session 239f88344c078ca8ffa403aa21628bdb.
[2024-10-23 22:50:19] [INFO    ] discord.gateway: Shard ID None has successfully RESUMED session 239f88344c078ca8ffa403aa21628bdb.
[2024-10-24 01:50:00] [INFO    ] discord.gateway: Shard ID None has successfully RESUMED session 239f88344c078ca8ffa403aa21628bdb.
[2024-10-24 04:15:30] [INFO    ] discord.gateway: Shard ID None has successfully RESUMED session 239f88344c078ca8ffa403aa21628bdb.
[2024-10-24 06:16:11] [INFO    ] discord.gateway: Shard ID None has successfully RESUMED session 239f88344c078ca8ffa403aa21628bdb.
[2024-10-24 07:03:08] [INFO    ] discord.gateway: Shard ID None has successfully RESUMED session 239f88344c078ca8ffa403aa21628bdb.
[2024-10-24 07:59:31] [INFO    ] discord.gateway: Shard ID None has successfully RESUMED session 239f88344c078ca8ffa403aa21628bdb.
[2024-10-24 10:30:42] [INFO    ] discord.gateway: Shard ID None has successfully RESUMED session 239f88344c078ca8ffa403aa21628bdb.
[2024-10-24 10:34:58] [INFO    ] discord.gateway: Shard ID None has successfully RESUMED session 239f88344c078ca8ffa403aa21628bdb.
[2024-10-24 12:38:02] [INFO    ] discord.gateway: Shard ID None has successfully RESUMED session 239f88344c078ca8ffa403aa21628bdb.
[2024-10-24 13:14:25] [INFO    ] discord.gateway: Shard ID None has successfully RESUMED session 239f88344c078ca8ffa403aa21628bdb.
[2024-10-24 15:10:19] [INFO    ] discord.gateway: Shard ID None has successfully RESUMED session 239f88344c078ca8ffa403aa21628bdb.
[2024-10-24 18:12:53] [INFO    ] discord.gateway: Shard ID None has successfully RESUMED session 239f88344c078ca8ffa403aa21628bdb.
[2024-10-24 19:24:58] [INFO    ] discord.gateway: Shard ID None has successfully RESUMED session 239f88344c078ca8ffa403aa21628bdb.
[2024-10-24 20:49:32] [INFO    ] discord.gateway: Shard ID None has successfully RESUMED session 239f88344c078ca8ffa403aa21628bdb.
[2024-10-24 22:14:57] [INFO    ] discord.gateway: Shard ID None has successfully RESUMED session 239f88344c078ca8ffa403aa21628bdb.
[2024-10-24 23:22:31] [INFO    ] discord.gateway: Shard ID None has successfully RESUMED session 239f88344c078ca8ffa403aa21628bdb.
[2024-10-25 02:03:24] [INFO    ] discord.gateway: Shard ID None has successfully RESUMED session 239f88344c078ca8ffa403aa21628bdb.
[2024-10-25 04:43:22] [INFO    ] discord.gateway: Shard ID None has successfully RESUMED session 239f88344c078ca8ffa403aa21628bdb.
[2024-10-25 05:30:07] [INFO    ] discord.gateway: Shard ID None has successfully RESUMED session 239f88344c078ca8ffa403aa21628bdb.
[2024-10-25 06:19:55] [INFO    ] discord.gateway: Shard ID None has successfully RESUMED session 239f88344c078ca8ffa403aa21628bdb.
[2024-10-25 07:19:22] [INFO    ] discord.gateway: Shard ID None has successfully RESUMED session 239f88344c078ca8ffa403aa21628bdb.
[2024-10-25 08:50:59] [INFO    ] discord.gateway: Shard ID None has successfully RESUMED session 239f88344c078ca8ffa403aa21628bdb.
[2024-10-25 11:07:04] [INFO    ] discord.gateway: Shard ID None has successfully RESUMED session 239f88344c078ca8ffa403aa21628bdb.
[2024-10-25 14:17:20] [INFO    ] discord.gateway: Shard ID None has successfully RESUMED session 239f88344c078ca8ffa403aa21628bdb.
[2024-10-25 16:12:16] [INFO    ] discord.gateway: Shard ID None has successfully RESUMED session 239f88344c078ca8ffa403aa21628bdb.
[2024-10-25 17:12:47] [INFO    ] discord.gateway: Shard ID None has successfully RESUMED session 239f88344c078ca8ffa403aa21628bdb.
[2024-10-25 21:04:19] [INFO    ] discord.gateway: Shard ID None has successfully RESUMED session 239f88344c078ca8ffa403aa21628bdb.
[2024-10-25 21:45:03] [INFO    ] discord.gateway: Shard ID None has successfully RESUMED session 239f88344c078ca8ffa403aa21628bdb.
[2024-10-25 22:39:17] [INFO    ] discord.gateway: Shard ID None has successfully RESUMED session 239f88344c078ca8ffa403aa21628bdb.
[2024-10-26 00:01:16] [INFO    ] discord.gateway: Shard ID None has successfully RESUMED session 239f88344c078ca8ffa403aa21628bdb.
[2024-10-26 03:19:01] [INFO    ] discord.gateway: Shard ID None has successfully RESUMED session 239f88344c078ca8ffa403aa21628bdb.
[2024-10-26 05:58:27] [INFO    ] discord.gateway: Shard ID None has successfully RESUMED session 239f88344c078ca8ffa403aa21628bdb.
[2024-10-26 06:00:30] [INFO    ] discord.gateway: Shard ID None has successfully RESUMED session 239f88344c078ca8ffa403aa21628bdb.
[2024-10-26 09:32:18] [INFO    ] discord.gateway: Shard ID None has successfully RESUMED session 239f88344c078ca8ffa403aa21628bdb.
[2024-10-26 10:12:10] [INFO    ] discord.gateway: Shard ID None has successfully RESUMED session 239f88344c078ca8ffa403aa21628bdb.
[2024-10-26 11:10:37] [INFO    ] discord.gateway: Shard ID None has successfully RESUMED session 239f88344c078ca8ffa403aa21628bdb.
[2024-10-26 11:45:46] [INFO    ] discord.gateway: Shard ID None has successfully RESUMED session 239f88344c078ca8ffa403aa21628bdb.
[2024-10-26 12:25:16] [ERROR   ] discord.client: Attempting a reconnect in 1.29s
Traceback (most recent call last):
  File "/home/fizr07/Desktop/progProjects/bots/CISbot/botenv/lib/python3.12/site-packages/aiohttp/connector.py", line 1317, in _create_direct_connection
    hosts = await self._resolve_host(host, port, traces=traces)
            ^^^^^^^^^^^^^^^^^^^^^^^^^^^^^^^^^^^^^^^^^^^^^^^^^^^
  File "/home/fizr07/Desktop/progProjects/bots/CISbot/botenv/lib/python3.12/site-packages/aiohttp/connector.py", line 971, in _resolve_host
    return await asyncio.shield(resolved_host_task)
           ^^^^^^^^^^^^^^^^^^^^^^^^^^^^^^^^^^^^^^^^
  File "/home/fizr07/Desktop/progProjects/bots/CISbot/botenv/lib/python3.12/site-packages/aiohttp/connector.py", line 1002, in _resolve_host_with_throttle
    addrs = await self._resolver.resolve(host, port, family=self._family)
            ^^^^^^^^^^^^^^^^^^^^^^^^^^^^^^^^^^^^^^^^^^^^^^^^^^^^^^^^^^^^^
  File "/home/fizr07/Desktop/progProjects/bots/CISbot/botenv/lib/python3.12/site-packages/aiohttp/resolver.py", line 38, in resolve
    infos = await self._loop.getaddrinfo(
            ^^^^^^^^^^^^^^^^^^^^^^^^^^^^^
  File "/usr/lib/python3.12/asyncio/base_events.py", line 901, in getaddrinfo
    return await self.run_in_executor(
           ^^^^^^^^^^^^^^^^^^^^^^^^^^^
  File "/usr/lib/python3.12/concurrent/futures/thread.py", line 58, in run
    result = self.fn(*self.args, **self.kwargs)
             ^^^^^^^^^^^^^^^^^^^^^^^^^^^^^^^^^^
  File "/usr/lib/python3.12/socket.py", line 976, in getaddrinfo
    for res in _socket.getaddrinfo(host, port, family, type, proto, flags):
               ^^^^^^^^^^^^^^^^^^^^^^^^^^^^^^^^^^^^^^^^^^^^^^^^^^^^^^^^^^^
socket.gaierror: [Errno -2] Name or service not known

The above exception was the direct cause of the following exception:

Traceback (most recent call last):
  File "/home/fizr07/Desktop/progProjects/bots/CISbot/botenv/lib/python3.12/site-packages/discord/client.py", line 664, in connect
    self.ws = await asyncio.wait_for(coro, timeout=60.0)
              ^^^^^^^^^^^^^^^^^^^^^^^^^^^^^^^^^^^^^^^^^^
  File "/usr/lib/python3.12/asyncio/tasks.py", line 520, in wait_for
    return await fut
           ^^^^^^^^^
  File "/home/fizr07/Desktop/progProjects/bots/CISbot/botenv/lib/python3.12/site-packages/discord/gateway.py", line 374, in from_client
    socket = await client.http.ws_connect(str(url))
             ^^^^^^^^^^^^^^^^^^^^^^^^^^^^^^^^^^^^^^
  File "/home/fizr07/Desktop/progProjects/bots/CISbot/botenv/lib/python3.12/site-packages/discord/http.py", line 550, in ws_connect
    return await self.__session.ws_connect(url, **kwargs)
           ^^^^^^^^^^^^^^^^^^^^^^^^^^^^^^^^^^^^^^^^^^^^^^
  File "/home/fizr07/Desktop/progProjects/bots/CISbot/botenv/lib/python3.12/site-packages/aiohttp/client.py", line 937, in _ws_connect
    resp = await self.request(
           ^^^^^^^^^^^^^^^^^^^
  File "/home/fizr07/Desktop/progProjects/bots/CISbot/botenv/lib/python3.12/site-packages/aiohttp/client.py", line 663, in _request
    conn = await self._connector.connect(
           ^^^^^^^^^^^^^^^^^^^^^^^^^^^^^^
  File "/home/fizr07/Desktop/progProjects/bots/CISbot/botenv/lib/python3.12/site-packages/aiohttp/connector.py", line 563, in connect
    proto = await self._create_connection(req, traces, timeout)
            ^^^^^^^^^^^^^^^^^^^^^^^^^^^^^^^^^^^^^^^^^^^^^^^^^^^
  File "/home/fizr07/Desktop/progProjects/bots/CISbot/botenv/lib/python3.12/site-packages/aiohttp/connector.py", line 1032, in _create_connection
    _, proto = await self._create_direct_connection(req, traces, timeout)
               ^^^^^^^^^^^^^^^^^^^^^^^^^^^^^^^^^^^^^^^^^^^^^^^^^^^^^^^^^^
  File "/home/fizr07/Desktop/progProjects/bots/CISbot/botenv/lib/python3.12/site-packages/aiohttp/connector.py", line 1323, in _create_direct_connection
    raise ClientConnectorDNSError(req.connection_key, exc) from exc
aiohttp.client_exceptions.ClientConnectorDNSError: Cannot connect to host gateway-us-east1-c.discord.gg:443 ssl:default [Name or service not known]
[2024-10-26 12:25:17] [ERROR   ] discord.client: Attempting a reconnect in 2.37s
Traceback (most recent call last):
  File "/home/fizr07/Desktop/progProjects/bots/CISbot/botenv/lib/python3.12/site-packages/aiohttp/connector.py", line 1317, in _create_direct_connection
    hosts = await self._resolve_host(host, port, traces=traces)
            ^^^^^^^^^^^^^^^^^^^^^^^^^^^^^^^^^^^^^^^^^^^^^^^^^^^
  File "/home/fizr07/Desktop/progProjects/bots/CISbot/botenv/lib/python3.12/site-packages/aiohttp/connector.py", line 971, in _resolve_host
    return await asyncio.shield(resolved_host_task)
           ^^^^^^^^^^^^^^^^^^^^^^^^^^^^^^^^^^^^^^^^
  File "/home/fizr07/Desktop/progProjects/bots/CISbot/botenv/lib/python3.12/site-packages/aiohttp/connector.py", line 1002, in _resolve_host_with_throttle
    addrs = await self._resolver.resolve(host, port, family=self._family)
            ^^^^^^^^^^^^^^^^^^^^^^^^^^^^^^^^^^^^^^^^^^^^^^^^^^^^^^^^^^^^^
  File "/home/fizr07/Desktop/progProjects/bots/CISbot/botenv/lib/python3.12/site-packages/aiohttp/resolver.py", line 38, in resolve
    infos = await self._loop.getaddrinfo(
            ^^^^^^^^^^^^^^^^^^^^^^^^^^^^^
  File "/usr/lib/python3.12/asyncio/base_events.py", line 901, in getaddrinfo
    return await self.run_in_executor(
           ^^^^^^^^^^^^^^^^^^^^^^^^^^^
  File "/usr/lib/python3.12/concurrent/futures/thread.py", line 58, in run
    result = self.fn(*self.args, **self.kwargs)
             ^^^^^^^^^^^^^^^^^^^^^^^^^^^^^^^^^^
  File "/usr/lib/python3.12/socket.py", line 976, in getaddrinfo
    for res in _socket.getaddrinfo(host, port, family, type, proto, flags):
               ^^^^^^^^^^^^^^^^^^^^^^^^^^^^^^^^^^^^^^^^^^^^^^^^^^^^^^^^^^^
socket.gaierror: [Errno -2] Name or service not known

The above exception was the direct cause of the following exception:

Traceback (most recent call last):
  File "/home/fizr07/Desktop/progProjects/bots/CISbot/botenv/lib/python3.12/site-packages/discord/client.py", line 664, in connect
    self.ws = await asyncio.wait_for(coro, timeout=60.0)
              ^^^^^^^^^^^^^^^^^^^^^^^^^^^^^^^^^^^^^^^^^^
  File "/usr/lib/python3.12/asyncio/tasks.py", line 520, in wait_for
    return await fut
           ^^^^^^^^^
  File "/home/fizr07/Desktop/progProjects/bots/CISbot/botenv/lib/python3.12/site-packages/discord/gateway.py", line 374, in from_client
    socket = await client.http.ws_connect(str(url))
             ^^^^^^^^^^^^^^^^^^^^^^^^^^^^^^^^^^^^^^
  File "/home/fizr07/Desktop/progProjects/bots/CISbot/botenv/lib/python3.12/site-packages/discord/http.py", line 550, in ws_connect
    return await self.__session.ws_connect(url, **kwargs)
           ^^^^^^^^^^^^^^^^^^^^^^^^^^^^^^^^^^^^^^^^^^^^^^
  File "/home/fizr07/Desktop/progProjects/bots/CISbot/botenv/lib/python3.12/site-packages/aiohttp/client.py", line 937, in _ws_connect
    resp = await self.request(
           ^^^^^^^^^^^^^^^^^^^
  File "/home/fizr07/Desktop/progProjects/bots/CISbot/botenv/lib/python3.12/site-packages/aiohttp/client.py", line 663, in _request
    conn = await self._connector.connect(
           ^^^^^^^^^^^^^^^^^^^^^^^^^^^^^^
  File "/home/fizr07/Desktop/progProjects/bots/CISbot/botenv/lib/python3.12/site-packages/aiohttp/connector.py", line 563, in connect
    proto = await self._create_connection(req, traces, timeout)
            ^^^^^^^^^^^^^^^^^^^^^^^^^^^^^^^^^^^^^^^^^^^^^^^^^^^
  File "/home/fizr07/Desktop/progProjects/bots/CISbot/botenv/lib/python3.12/site-packages/aiohttp/connector.py", line 1032, in _create_connection
    _, proto = await self._create_direct_connection(req, traces, timeout)
               ^^^^^^^^^^^^^^^^^^^^^^^^^^^^^^^^^^^^^^^^^^^^^^^^^^^^^^^^^^
  File "/home/fizr07/Desktop/progProjects/bots/CISbot/botenv/lib/python3.12/site-packages/aiohttp/connector.py", line 1323, in _create_direct_connection
    raise ClientConnectorDNSError(req.connection_key, exc) from exc
aiohttp.client_exceptions.ClientConnectorDNSError: Cannot connect to host gateway-us-east1-c.discord.gg:443 ssl:default [Name or service not known]
[2024-10-26 12:25:19] [ERROR   ] discord.client: Attempting a reconnect in 5.16s
Traceback (most recent call last):
  File "/home/fizr07/Desktop/progProjects/bots/CISbot/botenv/lib/python3.12/site-packages/aiohttp/connector.py", line 1317, in _create_direct_connection
    hosts = await self._resolve_host(host, port, traces=traces)
            ^^^^^^^^^^^^^^^^^^^^^^^^^^^^^^^^^^^^^^^^^^^^^^^^^^^
  File "/home/fizr07/Desktop/progProjects/bots/CISbot/botenv/lib/python3.12/site-packages/aiohttp/connector.py", line 971, in _resolve_host
    return await asyncio.shield(resolved_host_task)
           ^^^^^^^^^^^^^^^^^^^^^^^^^^^^^^^^^^^^^^^^
  File "/home/fizr07/Desktop/progProjects/bots/CISbot/botenv/lib/python3.12/site-packages/aiohttp/connector.py", line 1002, in _resolve_host_with_throttle
    addrs = await self._resolver.resolve(host, port, family=self._family)
            ^^^^^^^^^^^^^^^^^^^^^^^^^^^^^^^^^^^^^^^^^^^^^^^^^^^^^^^^^^^^^
  File "/home/fizr07/Desktop/progProjects/bots/CISbot/botenv/lib/python3.12/site-packages/aiohttp/resolver.py", line 38, in resolve
    infos = await self._loop.getaddrinfo(
            ^^^^^^^^^^^^^^^^^^^^^^^^^^^^^
  File "/usr/lib/python3.12/asyncio/base_events.py", line 901, in getaddrinfo
    return await self.run_in_executor(
           ^^^^^^^^^^^^^^^^^^^^^^^^^^^
  File "/usr/lib/python3.12/concurrent/futures/thread.py", line 58, in run
    result = self.fn(*self.args, **self.kwargs)
             ^^^^^^^^^^^^^^^^^^^^^^^^^^^^^^^^^^
  File "/usr/lib/python3.12/socket.py", line 976, in getaddrinfo
    for res in _socket.getaddrinfo(host, port, family, type, proto, flags):
               ^^^^^^^^^^^^^^^^^^^^^^^^^^^^^^^^^^^^^^^^^^^^^^^^^^^^^^^^^^^
socket.gaierror: [Errno -2] Name or service not known

The above exception was the direct cause of the following exception:

Traceback (most recent call last):
  File "/home/fizr07/Desktop/progProjects/bots/CISbot/botenv/lib/python3.12/site-packages/discord/client.py", line 664, in connect
    self.ws = await asyncio.wait_for(coro, timeout=60.0)
              ^^^^^^^^^^^^^^^^^^^^^^^^^^^^^^^^^^^^^^^^^^
  File "/usr/lib/python3.12/asyncio/tasks.py", line 520, in wait_for
    return await fut
           ^^^^^^^^^
  File "/home/fizr07/Desktop/progProjects/bots/CISbot/botenv/lib/python3.12/site-packages/discord/gateway.py", line 374, in from_client
    socket = await client.http.ws_connect(str(url))
             ^^^^^^^^^^^^^^^^^^^^^^^^^^^^^^^^^^^^^^
  File "/home/fizr07/Desktop/progProjects/bots/CISbot/botenv/lib/python3.12/site-packages/discord/http.py", line 550, in ws_connect
    return await self.__session.ws_connect(url, **kwargs)
           ^^^^^^^^^^^^^^^^^^^^^^^^^^^^^^^^^^^^^^^^^^^^^^
  File "/home/fizr07/Desktop/progProjects/bots/CISbot/botenv/lib/python3.12/site-packages/aiohttp/client.py", line 937, in _ws_connect
    resp = await self.request(
           ^^^^^^^^^^^^^^^^^^^
  File "/home/fizr07/Desktop/progProjects/bots/CISbot/botenv/lib/python3.12/site-packages/aiohttp/client.py", line 663, in _request
    conn = await self._connector.connect(
           ^^^^^^^^^^^^^^^^^^^^^^^^^^^^^^
  File "/home/fizr07/Desktop/progProjects/bots/CISbot/botenv/lib/python3.12/site-packages/aiohttp/connector.py", line 563, in connect
    proto = await self._create_connection(req, traces, timeout)
            ^^^^^^^^^^^^^^^^^^^^^^^^^^^^^^^^^^^^^^^^^^^^^^^^^^^
  File "/home/fizr07/Desktop/progProjects/bots/CISbot/botenv/lib/python3.12/site-packages/aiohttp/connector.py", line 1032, in _create_connection
    _, proto = await self._create_direct_connection(req, traces, timeout)
               ^^^^^^^^^^^^^^^^^^^^^^^^^^^^^^^^^^^^^^^^^^^^^^^^^^^^^^^^^^
  File "/home/fizr07/Desktop/progProjects/bots/CISbot/botenv/lib/python3.12/site-packages/aiohttp/connector.py", line 1323, in _create_direct_connection
    raise ClientConnectorDNSError(req.connection_key, exc) from exc
aiohttp.client_exceptions.ClientConnectorDNSError: Cannot connect to host gateway-us-east1-c.discord.gg:443 ssl:default [Name or service not known]
[2024-10-26 12:25:25] [ERROR   ] discord.client: Attempting a reconnect in 12.46s
Traceback (most recent call last):
  File "/home/fizr07/Desktop/progProjects/bots/CISbot/botenv/lib/python3.12/site-packages/aiohttp/connector.py", line 1317, in _create_direct_connection
    hosts = await self._resolve_host(host, port, traces=traces)
            ^^^^^^^^^^^^^^^^^^^^^^^^^^^^^^^^^^^^^^^^^^^^^^^^^^^
  File "/home/fizr07/Desktop/progProjects/bots/CISbot/botenv/lib/python3.12/site-packages/aiohttp/connector.py", line 971, in _resolve_host
    return await asyncio.shield(resolved_host_task)
           ^^^^^^^^^^^^^^^^^^^^^^^^^^^^^^^^^^^^^^^^
  File "/home/fizr07/Desktop/progProjects/bots/CISbot/botenv/lib/python3.12/site-packages/aiohttp/connector.py", line 1002, in _resolve_host_with_throttle
    addrs = await self._resolver.resolve(host, port, family=self._family)
            ^^^^^^^^^^^^^^^^^^^^^^^^^^^^^^^^^^^^^^^^^^^^^^^^^^^^^^^^^^^^^
  File "/home/fizr07/Desktop/progProjects/bots/CISbot/botenv/lib/python3.12/site-packages/aiohttp/resolver.py", line 38, in resolve
    infos = await self._loop.getaddrinfo(
            ^^^^^^^^^^^^^^^^^^^^^^^^^^^^^
  File "/usr/lib/python3.12/asyncio/base_events.py", line 901, in getaddrinfo
    return await self.run_in_executor(
           ^^^^^^^^^^^^^^^^^^^^^^^^^^^
  File "/usr/lib/python3.12/concurrent/futures/thread.py", line 58, in run
    result = self.fn(*self.args, **self.kwargs)
             ^^^^^^^^^^^^^^^^^^^^^^^^^^^^^^^^^^
  File "/usr/lib/python3.12/socket.py", line 976, in getaddrinfo
    for res in _socket.getaddrinfo(host, port, family, type, proto, flags):
               ^^^^^^^^^^^^^^^^^^^^^^^^^^^^^^^^^^^^^^^^^^^^^^^^^^^^^^^^^^^
socket.gaierror: [Errno -2] Name or service not known

The above exception was the direct cause of the following exception:

Traceback (most recent call last):
  File "/home/fizr07/Desktop/progProjects/bots/CISbot/botenv/lib/python3.12/site-packages/discord/client.py", line 664, in connect
    self.ws = await asyncio.wait_for(coro, timeout=60.0)
              ^^^^^^^^^^^^^^^^^^^^^^^^^^^^^^^^^^^^^^^^^^
  File "/usr/lib/python3.12/asyncio/tasks.py", line 520, in wait_for
    return await fut
           ^^^^^^^^^
  File "/home/fizr07/Desktop/progProjects/bots/CISbot/botenv/lib/python3.12/site-packages/discord/gateway.py", line 374, in from_client
    socket = await client.http.ws_connect(str(url))
             ^^^^^^^^^^^^^^^^^^^^^^^^^^^^^^^^^^^^^^
  File "/home/fizr07/Desktop/progProjects/bots/CISbot/botenv/lib/python3.12/site-packages/discord/http.py", line 550, in ws_connect
    return await self.__session.ws_connect(url, **kwargs)
           ^^^^^^^^^^^^^^^^^^^^^^^^^^^^^^^^^^^^^^^^^^^^^^
  File "/home/fizr07/Desktop/progProjects/bots/CISbot/botenv/lib/python3.12/site-packages/aiohttp/client.py", line 937, in _ws_connect
    resp = await self.request(
           ^^^^^^^^^^^^^^^^^^^
  File "/home/fizr07/Desktop/progProjects/bots/CISbot/botenv/lib/python3.12/site-packages/aiohttp/client.py", line 663, in _request
    conn = await self._connector.connect(
           ^^^^^^^^^^^^^^^^^^^^^^^^^^^^^^
  File "/home/fizr07/Desktop/progProjects/bots/CISbot/botenv/lib/python3.12/site-packages/aiohttp/connector.py", line 563, in connect
    proto = await self._create_connection(req, traces, timeout)
            ^^^^^^^^^^^^^^^^^^^^^^^^^^^^^^^^^^^^^^^^^^^^^^^^^^^
  File "/home/fizr07/Desktop/progProjects/bots/CISbot/botenv/lib/python3.12/site-packages/aiohttp/connector.py", line 1032, in _create_connection
    _, proto = await self._create_direct_connection(req, traces, timeout)
               ^^^^^^^^^^^^^^^^^^^^^^^^^^^^^^^^^^^^^^^^^^^^^^^^^^^^^^^^^^
  File "/home/fizr07/Desktop/progProjects/bots/CISbot/botenv/lib/python3.12/site-packages/aiohttp/connector.py", line 1323, in _create_direct_connection
    raise ClientConnectorDNSError(req.connection_key, exc) from exc
aiohttp.client_exceptions.ClientConnectorDNSError: Cannot connect to host gateway-us-east1-c.discord.gg:443 ssl:default [Name or service not known]
[2024-10-26 12:25:37] [ERROR   ] discord.client: Attempting a reconnect in 28.37s
Traceback (most recent call last):
  File "/home/fizr07/Desktop/progProjects/bots/CISbot/botenv/lib/python3.12/site-packages/aiohttp/connector.py", line 1317, in _create_direct_connection
    hosts = await self._resolve_host(host, port, traces=traces)
            ^^^^^^^^^^^^^^^^^^^^^^^^^^^^^^^^^^^^^^^^^^^^^^^^^^^
  File "/home/fizr07/Desktop/progProjects/bots/CISbot/botenv/lib/python3.12/site-packages/aiohttp/connector.py", line 971, in _resolve_host
    return await asyncio.shield(resolved_host_task)
           ^^^^^^^^^^^^^^^^^^^^^^^^^^^^^^^^^^^^^^^^
  File "/home/fizr07/Desktop/progProjects/bots/CISbot/botenv/lib/python3.12/site-packages/aiohttp/connector.py", line 1002, in _resolve_host_with_throttle
    addrs = await self._resolver.resolve(host, port, family=self._family)
            ^^^^^^^^^^^^^^^^^^^^^^^^^^^^^^^^^^^^^^^^^^^^^^^^^^^^^^^^^^^^^
  File "/home/fizr07/Desktop/progProjects/bots/CISbot/botenv/lib/python3.12/site-packages/aiohttp/resolver.py", line 38, in resolve
    infos = await self._loop.getaddrinfo(
            ^^^^^^^^^^^^^^^^^^^^^^^^^^^^^
  File "/usr/lib/python3.12/asyncio/base_events.py", line 901, in getaddrinfo
    return await self.run_in_executor(
           ^^^^^^^^^^^^^^^^^^^^^^^^^^^
  File "/usr/lib/python3.12/concurrent/futures/thread.py", line 58, in run
    result = self.fn(*self.args, **self.kwargs)
             ^^^^^^^^^^^^^^^^^^^^^^^^^^^^^^^^^^
  File "/usr/lib/python3.12/socket.py", line 976, in getaddrinfo
    for res in _socket.getaddrinfo(host, port, family, type, proto, flags):
               ^^^^^^^^^^^^^^^^^^^^^^^^^^^^^^^^^^^^^^^^^^^^^^^^^^^^^^^^^^^
socket.gaierror: [Errno -2] Name or service not known

The above exception was the direct cause of the following exception:

Traceback (most recent call last):
  File "/home/fizr07/Desktop/progProjects/bots/CISbot/botenv/lib/python3.12/site-packages/discord/client.py", line 664, in connect
    self.ws = await asyncio.wait_for(coro, timeout=60.0)
              ^^^^^^^^^^^^^^^^^^^^^^^^^^^^^^^^^^^^^^^^^^
  File "/usr/lib/python3.12/asyncio/tasks.py", line 520, in wait_for
    return await fut
           ^^^^^^^^^
  File "/home/fizr07/Desktop/progProjects/bots/CISbot/botenv/lib/python3.12/site-packages/discord/gateway.py", line 374, in from_client
    socket = await client.http.ws_connect(str(url))
             ^^^^^^^^^^^^^^^^^^^^^^^^^^^^^^^^^^^^^^
  File "/home/fizr07/Desktop/progProjects/bots/CISbot/botenv/lib/python3.12/site-packages/discord/http.py", line 550, in ws_connect
    return await self.__session.ws_connect(url, **kwargs)
           ^^^^^^^^^^^^^^^^^^^^^^^^^^^^^^^^^^^^^^^^^^^^^^
  File "/home/fizr07/Desktop/progProjects/bots/CISbot/botenv/lib/python3.12/site-packages/aiohttp/client.py", line 937, in _ws_connect
    resp = await self.request(
           ^^^^^^^^^^^^^^^^^^^
  File "/home/fizr07/Desktop/progProjects/bots/CISbot/botenv/lib/python3.12/site-packages/aiohttp/client.py", line 663, in _request
    conn = await self._connector.connect(
           ^^^^^^^^^^^^^^^^^^^^^^^^^^^^^^
  File "/home/fizr07/Desktop/progProjects/bots/CISbot/botenv/lib/python3.12/site-packages/aiohttp/connector.py", line 563, in connect
    proto = await self._create_connection(req, traces, timeout)
            ^^^^^^^^^^^^^^^^^^^^^^^^^^^^^^^^^^^^^^^^^^^^^^^^^^^
  File "/home/fizr07/Desktop/progProjects/bots/CISbot/botenv/lib/python3.12/site-packages/aiohttp/connector.py", line 1032, in _create_connection
    _, proto = await self._create_direct_connection(req, traces, timeout)
               ^^^^^^^^^^^^^^^^^^^^^^^^^^^^^^^^^^^^^^^^^^^^^^^^^^^^^^^^^^
  File "/home/fizr07/Desktop/progProjects/bots/CISbot/botenv/lib/python3.12/site-packages/aiohttp/connector.py", line 1323, in _create_direct_connection
    raise ClientConnectorDNSError(req.connection_key, exc) from exc
aiohttp.client_exceptions.ClientConnectorDNSError: Cannot connect to host gateway-us-east1-c.discord.gg:443 ssl:default [Name or service not known]
[2024-10-26 12:26:06] [INFO    ] discord.gateway: Shard ID None has successfully RESUMED session 239f88344c078ca8ffa403aa21628bdb.
[2024-10-26 12:53:55] [ERROR   ] discord.client: Attempting a reconnect in 47.19s
Traceback (most recent call last):
  File "/home/fizr07/Desktop/progProjects/bots/CISbot/botenv/lib/python3.12/site-packages/aiohttp/connector.py", line 1317, in _create_direct_connection
    hosts = await self._resolve_host(host, port, traces=traces)
            ^^^^^^^^^^^^^^^^^^^^^^^^^^^^^^^^^^^^^^^^^^^^^^^^^^^
  File "/home/fizr07/Desktop/progProjects/bots/CISbot/botenv/lib/python3.12/site-packages/aiohttp/connector.py", line 971, in _resolve_host
    return await asyncio.shield(resolved_host_task)
           ^^^^^^^^^^^^^^^^^^^^^^^^^^^^^^^^^^^^^^^^
  File "/home/fizr07/Desktop/progProjects/bots/CISbot/botenv/lib/python3.12/site-packages/aiohttp/connector.py", line 1002, in _resolve_host_with_throttle
    addrs = await self._resolver.resolve(host, port, family=self._family)
            ^^^^^^^^^^^^^^^^^^^^^^^^^^^^^^^^^^^^^^^^^^^^^^^^^^^^^^^^^^^^^
  File "/home/fizr07/Desktop/progProjects/bots/CISbot/botenv/lib/python3.12/site-packages/aiohttp/resolver.py", line 38, in resolve
    infos = await self._loop.getaddrinfo(
            ^^^^^^^^^^^^^^^^^^^^^^^^^^^^^
  File "/usr/lib/python3.12/asyncio/base_events.py", line 901, in getaddrinfo
    return await self.run_in_executor(
           ^^^^^^^^^^^^^^^^^^^^^^^^^^^
  File "/usr/lib/python3.12/concurrent/futures/thread.py", line 58, in run
    result = self.fn(*self.args, **self.kwargs)
             ^^^^^^^^^^^^^^^^^^^^^^^^^^^^^^^^^^
  File "/usr/lib/python3.12/socket.py", line 976, in getaddrinfo
    for res in _socket.getaddrinfo(host, port, family, type, proto, flags):
               ^^^^^^^^^^^^^^^^^^^^^^^^^^^^^^^^^^^^^^^^^^^^^^^^^^^^^^^^^^^
socket.gaierror: [Errno -2] Name or service not known

The above exception was the direct cause of the following exception:

Traceback (most recent call last):
  File "/home/fizr07/Desktop/progProjects/bots/CISbot/botenv/lib/python3.12/site-packages/discord/client.py", line 664, in connect
    self.ws = await asyncio.wait_for(coro, timeout=60.0)
              ^^^^^^^^^^^^^^^^^^^^^^^^^^^^^^^^^^^^^^^^^^
  File "/usr/lib/python3.12/asyncio/tasks.py", line 520, in wait_for
    return await fut
           ^^^^^^^^^
  File "/home/fizr07/Desktop/progProjects/bots/CISbot/botenv/lib/python3.12/site-packages/discord/gateway.py", line 374, in from_client
    socket = await client.http.ws_connect(str(url))
             ^^^^^^^^^^^^^^^^^^^^^^^^^^^^^^^^^^^^^^
  File "/home/fizr07/Desktop/progProjects/bots/CISbot/botenv/lib/python3.12/site-packages/discord/http.py", line 550, in ws_connect
    return await self.__session.ws_connect(url, **kwargs)
           ^^^^^^^^^^^^^^^^^^^^^^^^^^^^^^^^^^^^^^^^^^^^^^
  File "/home/fizr07/Desktop/progProjects/bots/CISbot/botenv/lib/python3.12/site-packages/aiohttp/client.py", line 937, in _ws_connect
    resp = await self.request(
           ^^^^^^^^^^^^^^^^^^^
  File "/home/fizr07/Desktop/progProjects/bots/CISbot/botenv/lib/python3.12/site-packages/aiohttp/client.py", line 663, in _request
    conn = await self._connector.connect(
           ^^^^^^^^^^^^^^^^^^^^^^^^^^^^^^
  File "/home/fizr07/Desktop/progProjects/bots/CISbot/botenv/lib/python3.12/site-packages/aiohttp/connector.py", line 563, in connect
    proto = await self._create_connection(req, traces, timeout)
            ^^^^^^^^^^^^^^^^^^^^^^^^^^^^^^^^^^^^^^^^^^^^^^^^^^^
  File "/home/fizr07/Desktop/progProjects/bots/CISbot/botenv/lib/python3.12/site-packages/aiohttp/connector.py", line 1032, in _create_connection
    _, proto = await self._create_direct_connection(req, traces, timeout)
               ^^^^^^^^^^^^^^^^^^^^^^^^^^^^^^^^^^^^^^^^^^^^^^^^^^^^^^^^^^
  File "/home/fizr07/Desktop/progProjects/bots/CISbot/botenv/lib/python3.12/site-packages/aiohttp/connector.py", line 1323, in _create_direct_connection
    raise ClientConnectorDNSError(req.connection_key, exc) from exc
aiohttp.client_exceptions.ClientConnectorDNSError: Cannot connect to host gateway-us-east1-c.discord.gg:443 ssl:default [Name or service not known]
[2024-10-26 12:54:42] [ERROR   ] discord.client: Attempting a reconnect in 61.31s
Traceback (most recent call last):
  File "/home/fizr07/Desktop/progProjects/bots/CISbot/botenv/lib/python3.12/site-packages/aiohttp/connector.py", line 1317, in _create_direct_connection
    hosts = await self._resolve_host(host, port, traces=traces)
            ^^^^^^^^^^^^^^^^^^^^^^^^^^^^^^^^^^^^^^^^^^^^^^^^^^^
  File "/home/fizr07/Desktop/progProjects/bots/CISbot/botenv/lib/python3.12/site-packages/aiohttp/connector.py", line 971, in _resolve_host
    return await asyncio.shield(resolved_host_task)
           ^^^^^^^^^^^^^^^^^^^^^^^^^^^^^^^^^^^^^^^^
  File "/home/fizr07/Desktop/progProjects/bots/CISbot/botenv/lib/python3.12/site-packages/aiohttp/connector.py", line 1002, in _resolve_host_with_throttle
    addrs = await self._resolver.resolve(host, port, family=self._family)
            ^^^^^^^^^^^^^^^^^^^^^^^^^^^^^^^^^^^^^^^^^^^^^^^^^^^^^^^^^^^^^
  File "/home/fizr07/Desktop/progProjects/bots/CISbot/botenv/lib/python3.12/site-packages/aiohttp/resolver.py", line 38, in resolve
    infos = await self._loop.getaddrinfo(
            ^^^^^^^^^^^^^^^^^^^^^^^^^^^^^
  File "/usr/lib/python3.12/asyncio/base_events.py", line 901, in getaddrinfo
    return await self.run_in_executor(
           ^^^^^^^^^^^^^^^^^^^^^^^^^^^
  File "/usr/lib/python3.12/concurrent/futures/thread.py", line 58, in run
    result = self.fn(*self.args, **self.kwargs)
             ^^^^^^^^^^^^^^^^^^^^^^^^^^^^^^^^^^
  File "/usr/lib/python3.12/socket.py", line 976, in getaddrinfo
    for res in _socket.getaddrinfo(host, port, family, type, proto, flags):
               ^^^^^^^^^^^^^^^^^^^^^^^^^^^^^^^^^^^^^^^^^^^^^^^^^^^^^^^^^^^
socket.gaierror: [Errno -2] Name or service not known

The above exception was the direct cause of the following exception:

Traceback (most recent call last):
  File "/home/fizr07/Desktop/progProjects/bots/CISbot/botenv/lib/python3.12/site-packages/discord/client.py", line 664, in connect
    self.ws = await asyncio.wait_for(coro, timeout=60.0)
              ^^^^^^^^^^^^^^^^^^^^^^^^^^^^^^^^^^^^^^^^^^
  File "/usr/lib/python3.12/asyncio/tasks.py", line 520, in wait_for
    return await fut
           ^^^^^^^^^
  File "/home/fizr07/Desktop/progProjects/bots/CISbot/botenv/lib/python3.12/site-packages/discord/gateway.py", line 374, in from_client
    socket = await client.http.ws_connect(str(url))
             ^^^^^^^^^^^^^^^^^^^^^^^^^^^^^^^^^^^^^^
  File "/home/fizr07/Desktop/progProjects/bots/CISbot/botenv/lib/python3.12/site-packages/discord/http.py", line 550, in ws_connect
    return await self.__session.ws_connect(url, **kwargs)
           ^^^^^^^^^^^^^^^^^^^^^^^^^^^^^^^^^^^^^^^^^^^^^^
  File "/home/fizr07/Desktop/progProjects/bots/CISbot/botenv/lib/python3.12/site-packages/aiohttp/client.py", line 937, in _ws_connect
    resp = await self.request(
           ^^^^^^^^^^^^^^^^^^^
  File "/home/fizr07/Desktop/progProjects/bots/CISbot/botenv/lib/python3.12/site-packages/aiohttp/client.py", line 663, in _request
    conn = await self._connector.connect(
           ^^^^^^^^^^^^^^^^^^^^^^^^^^^^^^
  File "/home/fizr07/Desktop/progProjects/bots/CISbot/botenv/lib/python3.12/site-packages/aiohttp/connector.py", line 563, in connect
    proto = await self._create_connection(req, traces, timeout)
            ^^^^^^^^^^^^^^^^^^^^^^^^^^^^^^^^^^^^^^^^^^^^^^^^^^^
  File "/home/fizr07/Desktop/progProjects/bots/CISbot/botenv/lib/python3.12/site-packages/aiohttp/connector.py", line 1032, in _create_connection
    _, proto = await self._create_direct_connection(req, traces, timeout)
               ^^^^^^^^^^^^^^^^^^^^^^^^^^^^^^^^^^^^^^^^^^^^^^^^^^^^^^^^^^
  File "/home/fizr07/Desktop/progProjects/bots/CISbot/botenv/lib/python3.12/site-packages/aiohttp/connector.py", line 1323, in _create_direct_connection
    raise ClientConnectorDNSError(req.connection_key, exc) from exc
aiohttp.client_exceptions.ClientConnectorDNSError: Cannot connect to host gateway-us-east1-c.discord.gg:443 ssl:default [Name or service not known]
[2024-10-26 12:55:44] [INFO    ] discord.gateway: Shard ID None session has been invalidated.
[2024-10-26 12:55:49] [INFO    ] discord.gateway: Shard ID None has connected to Gateway (Session ID: a4c523e31dd8e7d98a3157b065afb9da).
[2024-10-26 14:15:03] [INFO    ] discord.gateway: Shard ID None has successfully RESUMED session a4c523e31dd8e7d98a3157b065afb9da.
[2024-10-26 17:24:14] [INFO    ] discord.gateway: Shard ID None has successfully RESUMED session a4c523e31dd8e7d98a3157b065afb9da.
[2024-10-26 19:28:16] [INFO    ] discord.gateway: Shard ID None has successfully RESUMED session a4c523e31dd8e7d98a3157b065afb9da.
[2024-10-26 21:02:19] [INFO    ] discord.gateway: Shard ID None has successfully RESUMED session a4c523e31dd8e7d98a3157b065afb9da.
[2024-10-26 21:51:26] [ERROR   ] discord.client: Attempting a reconnect in 1.62s
Traceback (most recent call last):
  File "/home/fizr07/Desktop/progProjects/bots/CISbot/botenv/lib/python3.12/site-packages/aiohttp/connector.py", line 1317, in _create_direct_connection
    hosts = await self._resolve_host(host, port, traces=traces)
            ^^^^^^^^^^^^^^^^^^^^^^^^^^^^^^^^^^^^^^^^^^^^^^^^^^^
  File "/home/fizr07/Desktop/progProjects/bots/CISbot/botenv/lib/python3.12/site-packages/aiohttp/connector.py", line 971, in _resolve_host
    return await asyncio.shield(resolved_host_task)
           ^^^^^^^^^^^^^^^^^^^^^^^^^^^^^^^^^^^^^^^^
  File "/home/fizr07/Desktop/progProjects/bots/CISbot/botenv/lib/python3.12/site-packages/aiohttp/connector.py", line 1002, in _resolve_host_with_throttle
    addrs = await self._resolver.resolve(host, port, family=self._family)
            ^^^^^^^^^^^^^^^^^^^^^^^^^^^^^^^^^^^^^^^^^^^^^^^^^^^^^^^^^^^^^
  File "/home/fizr07/Desktop/progProjects/bots/CISbot/botenv/lib/python3.12/site-packages/aiohttp/resolver.py", line 38, in resolve
    infos = await self._loop.getaddrinfo(
            ^^^^^^^^^^^^^^^^^^^^^^^^^^^^^
  File "/usr/lib/python3.12/asyncio/base_events.py", line 901, in getaddrinfo
    return await self.run_in_executor(
           ^^^^^^^^^^^^^^^^^^^^^^^^^^^
  File "/usr/lib/python3.12/concurrent/futures/thread.py", line 58, in run
    result = self.fn(*self.args, **self.kwargs)
             ^^^^^^^^^^^^^^^^^^^^^^^^^^^^^^^^^^
  File "/usr/lib/python3.12/socket.py", line 976, in getaddrinfo
    for res in _socket.getaddrinfo(host, port, family, type, proto, flags):
               ^^^^^^^^^^^^^^^^^^^^^^^^^^^^^^^^^^^^^^^^^^^^^^^^^^^^^^^^^^^
socket.gaierror: [Errno -2] Name or service not known

The above exception was the direct cause of the following exception:

Traceback (most recent call last):
  File "/home/fizr07/Desktop/progProjects/bots/CISbot/botenv/lib/python3.12/site-packages/discord/client.py", line 664, in connect
    self.ws = await asyncio.wait_for(coro, timeout=60.0)
              ^^^^^^^^^^^^^^^^^^^^^^^^^^^^^^^^^^^^^^^^^^
  File "/usr/lib/python3.12/asyncio/tasks.py", line 520, in wait_for
    return await fut
           ^^^^^^^^^
  File "/home/fizr07/Desktop/progProjects/bots/CISbot/botenv/lib/python3.12/site-packages/discord/gateway.py", line 374, in from_client
    socket = await client.http.ws_connect(str(url))
             ^^^^^^^^^^^^^^^^^^^^^^^^^^^^^^^^^^^^^^
  File "/home/fizr07/Desktop/progProjects/bots/CISbot/botenv/lib/python3.12/site-packages/discord/http.py", line 550, in ws_connect
    return await self.__session.ws_connect(url, **kwargs)
           ^^^^^^^^^^^^^^^^^^^^^^^^^^^^^^^^^^^^^^^^^^^^^^
  File "/home/fizr07/Desktop/progProjects/bots/CISbot/botenv/lib/python3.12/site-packages/aiohttp/client.py", line 937, in _ws_connect
    resp = await self.request(
           ^^^^^^^^^^^^^^^^^^^
  File "/home/fizr07/Desktop/progProjects/bots/CISbot/botenv/lib/python3.12/site-packages/aiohttp/client.py", line 663, in _request
    conn = await self._connector.connect(
           ^^^^^^^^^^^^^^^^^^^^^^^^^^^^^^
  File "/home/fizr07/Desktop/progProjects/bots/CISbot/botenv/lib/python3.12/site-packages/aiohttp/connector.py", line 563, in connect
    proto = await self._create_connection(req, traces, timeout)
            ^^^^^^^^^^^^^^^^^^^^^^^^^^^^^^^^^^^^^^^^^^^^^^^^^^^
  File "/home/fizr07/Desktop/progProjects/bots/CISbot/botenv/lib/python3.12/site-packages/aiohttp/connector.py", line 1032, in _create_connection
    _, proto = await self._create_direct_connection(req, traces, timeout)
               ^^^^^^^^^^^^^^^^^^^^^^^^^^^^^^^^^^^^^^^^^^^^^^^^^^^^^^^^^^
  File "/home/fizr07/Desktop/progProjects/bots/CISbot/botenv/lib/python3.12/site-packages/aiohttp/connector.py", line 1323, in _create_direct_connection
    raise ClientConnectorDNSError(req.connection_key, exc) from exc
aiohttp.client_exceptions.ClientConnectorDNSError: Cannot connect to host gateway-us-east1-c.discord.gg:443 ssl:default [Name or service not known]
[2024-10-26 21:51:28] [ERROR   ] discord.client: Attempting a reconnect in 2.59s
Traceback (most recent call last):
  File "/home/fizr07/Desktop/progProjects/bots/CISbot/botenv/lib/python3.12/site-packages/aiohttp/connector.py", line 1317, in _create_direct_connection
    hosts = await self._resolve_host(host, port, traces=traces)
            ^^^^^^^^^^^^^^^^^^^^^^^^^^^^^^^^^^^^^^^^^^^^^^^^^^^
  File "/home/fizr07/Desktop/progProjects/bots/CISbot/botenv/lib/python3.12/site-packages/aiohttp/connector.py", line 971, in _resolve_host
    return await asyncio.shield(resolved_host_task)
           ^^^^^^^^^^^^^^^^^^^^^^^^^^^^^^^^^^^^^^^^
  File "/home/fizr07/Desktop/progProjects/bots/CISbot/botenv/lib/python3.12/site-packages/aiohttp/connector.py", line 1002, in _resolve_host_with_throttle
    addrs = await self._resolver.resolve(host, port, family=self._family)
            ^^^^^^^^^^^^^^^^^^^^^^^^^^^^^^^^^^^^^^^^^^^^^^^^^^^^^^^^^^^^^
  File "/home/fizr07/Desktop/progProjects/bots/CISbot/botenv/lib/python3.12/site-packages/aiohttp/resolver.py", line 38, in resolve
    infos = await self._loop.getaddrinfo(
            ^^^^^^^^^^^^^^^^^^^^^^^^^^^^^
  File "/usr/lib/python3.12/asyncio/base_events.py", line 901, in getaddrinfo
    return await self.run_in_executor(
           ^^^^^^^^^^^^^^^^^^^^^^^^^^^
  File "/usr/lib/python3.12/concurrent/futures/thread.py", line 58, in run
    result = self.fn(*self.args, **self.kwargs)
             ^^^^^^^^^^^^^^^^^^^^^^^^^^^^^^^^^^
  File "/usr/lib/python3.12/socket.py", line 976, in getaddrinfo
    for res in _socket.getaddrinfo(host, port, family, type, proto, flags):
               ^^^^^^^^^^^^^^^^^^^^^^^^^^^^^^^^^^^^^^^^^^^^^^^^^^^^^^^^^^^
socket.gaierror: [Errno -2] Name or service not known

The above exception was the direct cause of the following exception:

Traceback (most recent call last):
  File "/home/fizr07/Desktop/progProjects/bots/CISbot/botenv/lib/python3.12/site-packages/discord/client.py", line 664, in connect
    self.ws = await asyncio.wait_for(coro, timeout=60.0)
              ^^^^^^^^^^^^^^^^^^^^^^^^^^^^^^^^^^^^^^^^^^
  File "/usr/lib/python3.12/asyncio/tasks.py", line 520, in wait_for
    return await fut
           ^^^^^^^^^
  File "/home/fizr07/Desktop/progProjects/bots/CISbot/botenv/lib/python3.12/site-packages/discord/gateway.py", line 374, in from_client
    socket = await client.http.ws_connect(str(url))
             ^^^^^^^^^^^^^^^^^^^^^^^^^^^^^^^^^^^^^^
  File "/home/fizr07/Desktop/progProjects/bots/CISbot/botenv/lib/python3.12/site-packages/discord/http.py", line 550, in ws_connect
    return await self.__session.ws_connect(url, **kwargs)
           ^^^^^^^^^^^^^^^^^^^^^^^^^^^^^^^^^^^^^^^^^^^^^^
  File "/home/fizr07/Desktop/progProjects/bots/CISbot/botenv/lib/python3.12/site-packages/aiohttp/client.py", line 937, in _ws_connect
    resp = await self.request(
           ^^^^^^^^^^^^^^^^^^^
  File "/home/fizr07/Desktop/progProjects/bots/CISbot/botenv/lib/python3.12/site-packages/aiohttp/client.py", line 663, in _request
    conn = await self._connector.connect(
           ^^^^^^^^^^^^^^^^^^^^^^^^^^^^^^
  File "/home/fizr07/Desktop/progProjects/bots/CISbot/botenv/lib/python3.12/site-packages/aiohttp/connector.py", line 563, in connect
    proto = await self._create_connection(req, traces, timeout)
            ^^^^^^^^^^^^^^^^^^^^^^^^^^^^^^^^^^^^^^^^^^^^^^^^^^^
  File "/home/fizr07/Desktop/progProjects/bots/CISbot/botenv/lib/python3.12/site-packages/aiohttp/connector.py", line 1032, in _create_connection
    _, proto = await self._create_direct_connection(req, traces, timeout)
               ^^^^^^^^^^^^^^^^^^^^^^^^^^^^^^^^^^^^^^^^^^^^^^^^^^^^^^^^^^
  File "/home/fizr07/Desktop/progProjects/bots/CISbot/botenv/lib/python3.12/site-packages/aiohttp/connector.py", line 1323, in _create_direct_connection
    raise ClientConnectorDNSError(req.connection_key, exc) from exc
aiohttp.client_exceptions.ClientConnectorDNSError: Cannot connect to host gateway-us-east1-c.discord.gg:443 ssl:default [Name or service not known]
[2024-10-26 21:51:31] [ERROR   ] discord.client: Attempting a reconnect in 1.57s
Traceback (most recent call last):
  File "/home/fizr07/Desktop/progProjects/bots/CISbot/botenv/lib/python3.12/site-packages/aiohttp/connector.py", line 1317, in _create_direct_connection
    hosts = await self._resolve_host(host, port, traces=traces)
            ^^^^^^^^^^^^^^^^^^^^^^^^^^^^^^^^^^^^^^^^^^^^^^^^^^^
  File "/home/fizr07/Desktop/progProjects/bots/CISbot/botenv/lib/python3.12/site-packages/aiohttp/connector.py", line 971, in _resolve_host
    return await asyncio.shield(resolved_host_task)
           ^^^^^^^^^^^^^^^^^^^^^^^^^^^^^^^^^^^^^^^^
  File "/home/fizr07/Desktop/progProjects/bots/CISbot/botenv/lib/python3.12/site-packages/aiohttp/connector.py", line 1002, in _resolve_host_with_throttle
    addrs = await self._resolver.resolve(host, port, family=self._family)
            ^^^^^^^^^^^^^^^^^^^^^^^^^^^^^^^^^^^^^^^^^^^^^^^^^^^^^^^^^^^^^
  File "/home/fizr07/Desktop/progProjects/bots/CISbot/botenv/lib/python3.12/site-packages/aiohttp/resolver.py", line 38, in resolve
    infos = await self._loop.getaddrinfo(
            ^^^^^^^^^^^^^^^^^^^^^^^^^^^^^
  File "/usr/lib/python3.12/asyncio/base_events.py", line 901, in getaddrinfo
    return await self.run_in_executor(
           ^^^^^^^^^^^^^^^^^^^^^^^^^^^
  File "/usr/lib/python3.12/concurrent/futures/thread.py", line 58, in run
    result = self.fn(*self.args, **self.kwargs)
             ^^^^^^^^^^^^^^^^^^^^^^^^^^^^^^^^^^
  File "/usr/lib/python3.12/socket.py", line 976, in getaddrinfo
    for res in _socket.getaddrinfo(host, port, family, type, proto, flags):
               ^^^^^^^^^^^^^^^^^^^^^^^^^^^^^^^^^^^^^^^^^^^^^^^^^^^^^^^^^^^
socket.gaierror: [Errno -2] Name or service not known

The above exception was the direct cause of the following exception:

Traceback (most recent call last):
  File "/home/fizr07/Desktop/progProjects/bots/CISbot/botenv/lib/python3.12/site-packages/discord/client.py", line 664, in connect
    self.ws = await asyncio.wait_for(coro, timeout=60.0)
              ^^^^^^^^^^^^^^^^^^^^^^^^^^^^^^^^^^^^^^^^^^
  File "/usr/lib/python3.12/asyncio/tasks.py", line 520, in wait_for
    return await fut
           ^^^^^^^^^
  File "/home/fizr07/Desktop/progProjects/bots/CISbot/botenv/lib/python3.12/site-packages/discord/gateway.py", line 374, in from_client
    socket = await client.http.ws_connect(str(url))
             ^^^^^^^^^^^^^^^^^^^^^^^^^^^^^^^^^^^^^^
  File "/home/fizr07/Desktop/progProjects/bots/CISbot/botenv/lib/python3.12/site-packages/discord/http.py", line 550, in ws_connect
    return await self.__session.ws_connect(url, **kwargs)
           ^^^^^^^^^^^^^^^^^^^^^^^^^^^^^^^^^^^^^^^^^^^^^^
  File "/home/fizr07/Desktop/progProjects/bots/CISbot/botenv/lib/python3.12/site-packages/aiohttp/client.py", line 937, in _ws_connect
    resp = await self.request(
           ^^^^^^^^^^^^^^^^^^^
  File "/home/fizr07/Desktop/progProjects/bots/CISbot/botenv/lib/python3.12/site-packages/aiohttp/client.py", line 663, in _request
    conn = await self._connector.connect(
           ^^^^^^^^^^^^^^^^^^^^^^^^^^^^^^
  File "/home/fizr07/Desktop/progProjects/bots/CISbot/botenv/lib/python3.12/site-packages/aiohttp/connector.py", line 563, in connect
    proto = await self._create_connection(req, traces, timeout)
            ^^^^^^^^^^^^^^^^^^^^^^^^^^^^^^^^^^^^^^^^^^^^^^^^^^^
  File "/home/fizr07/Desktop/progProjects/bots/CISbot/botenv/lib/python3.12/site-packages/aiohttp/connector.py", line 1032, in _create_connection
    _, proto = await self._create_direct_connection(req, traces, timeout)
               ^^^^^^^^^^^^^^^^^^^^^^^^^^^^^^^^^^^^^^^^^^^^^^^^^^^^^^^^^^
  File "/home/fizr07/Desktop/progProjects/bots/CISbot/botenv/lib/python3.12/site-packages/aiohttp/connector.py", line 1323, in _create_direct_connection
    raise ClientConnectorDNSError(req.connection_key, exc) from exc
aiohttp.client_exceptions.ClientConnectorDNSError: Cannot connect to host gateway-us-east1-c.discord.gg:443 ssl:default [Name or service not known]
[2024-10-26 21:51:32] [ERROR   ] discord.client: Attempting a reconnect in 0.25s
Traceback (most recent call last):
  File "/home/fizr07/Desktop/progProjects/bots/CISbot/botenv/lib/python3.12/site-packages/aiohttp/connector.py", line 1317, in _create_direct_connection
    hosts = await self._resolve_host(host, port, traces=traces)
            ^^^^^^^^^^^^^^^^^^^^^^^^^^^^^^^^^^^^^^^^^^^^^^^^^^^
  File "/home/fizr07/Desktop/progProjects/bots/CISbot/botenv/lib/python3.12/site-packages/aiohttp/connector.py", line 971, in _resolve_host
    return await asyncio.shield(resolved_host_task)
           ^^^^^^^^^^^^^^^^^^^^^^^^^^^^^^^^^^^^^^^^
  File "/home/fizr07/Desktop/progProjects/bots/CISbot/botenv/lib/python3.12/site-packages/aiohttp/connector.py", line 1002, in _resolve_host_with_throttle
    addrs = await self._resolver.resolve(host, port, family=self._family)
            ^^^^^^^^^^^^^^^^^^^^^^^^^^^^^^^^^^^^^^^^^^^^^^^^^^^^^^^^^^^^^
  File "/home/fizr07/Desktop/progProjects/bots/CISbot/botenv/lib/python3.12/site-packages/aiohttp/resolver.py", line 38, in resolve
    infos = await self._loop.getaddrinfo(
            ^^^^^^^^^^^^^^^^^^^^^^^^^^^^^
  File "/usr/lib/python3.12/asyncio/base_events.py", line 901, in getaddrinfo
    return await self.run_in_executor(
           ^^^^^^^^^^^^^^^^^^^^^^^^^^^
  File "/usr/lib/python3.12/concurrent/futures/thread.py", line 58, in run
    result = self.fn(*self.args, **self.kwargs)
             ^^^^^^^^^^^^^^^^^^^^^^^^^^^^^^^^^^
  File "/usr/lib/python3.12/socket.py", line 976, in getaddrinfo
    for res in _socket.getaddrinfo(host, port, family, type, proto, flags):
               ^^^^^^^^^^^^^^^^^^^^^^^^^^^^^^^^^^^^^^^^^^^^^^^^^^^^^^^^^^^
socket.gaierror: [Errno -2] Name or service not known

The above exception was the direct cause of the following exception:

Traceback (most recent call last):
  File "/home/fizr07/Desktop/progProjects/bots/CISbot/botenv/lib/python3.12/site-packages/discord/client.py", line 664, in connect
    self.ws = await asyncio.wait_for(coro, timeout=60.0)
              ^^^^^^^^^^^^^^^^^^^^^^^^^^^^^^^^^^^^^^^^^^
  File "/usr/lib/python3.12/asyncio/tasks.py", line 520, in wait_for
    return await fut
           ^^^^^^^^^
  File "/home/fizr07/Desktop/progProjects/bots/CISbot/botenv/lib/python3.12/site-packages/discord/gateway.py", line 374, in from_client
    socket = await client.http.ws_connect(str(url))
             ^^^^^^^^^^^^^^^^^^^^^^^^^^^^^^^^^^^^^^
  File "/home/fizr07/Desktop/progProjects/bots/CISbot/botenv/lib/python3.12/site-packages/discord/http.py", line 550, in ws_connect
    return await self.__session.ws_connect(url, **kwargs)
           ^^^^^^^^^^^^^^^^^^^^^^^^^^^^^^^^^^^^^^^^^^^^^^
  File "/home/fizr07/Desktop/progProjects/bots/CISbot/botenv/lib/python3.12/site-packages/aiohttp/client.py", line 937, in _ws_connect
    resp = await self.request(
           ^^^^^^^^^^^^^^^^^^^
  File "/home/fizr07/Desktop/progProjects/bots/CISbot/botenv/lib/python3.12/site-packages/aiohttp/client.py", line 663, in _request
    conn = await self._connector.connect(
           ^^^^^^^^^^^^^^^^^^^^^^^^^^^^^^
  File "/home/fizr07/Desktop/progProjects/bots/CISbot/botenv/lib/python3.12/site-packages/aiohttp/connector.py", line 563, in connect
    proto = await self._create_connection(req, traces, timeout)
            ^^^^^^^^^^^^^^^^^^^^^^^^^^^^^^^^^^^^^^^^^^^^^^^^^^^
  File "/home/fizr07/Desktop/progProjects/bots/CISbot/botenv/lib/python3.12/site-packages/aiohttp/connector.py", line 1032, in _create_connection
    _, proto = await self._create_direct_connection(req, traces, timeout)
               ^^^^^^^^^^^^^^^^^^^^^^^^^^^^^^^^^^^^^^^^^^^^^^^^^^^^^^^^^^
  File "/home/fizr07/Desktop/progProjects/bots/CISbot/botenv/lib/python3.12/site-packages/aiohttp/connector.py", line 1323, in _create_direct_connection
    raise ClientConnectorDNSError(req.connection_key, exc) from exc
aiohttp.client_exceptions.ClientConnectorDNSError: Cannot connect to host gateway-us-east1-c.discord.gg:443 ssl:default [Name or service not known]
[2024-10-26 21:51:32] [ERROR   ] discord.client: Attempting a reconnect in 31.07s
Traceback (most recent call last):
  File "/home/fizr07/Desktop/progProjects/bots/CISbot/botenv/lib/python3.12/site-packages/aiohttp/connector.py", line 1317, in _create_direct_connection
    hosts = await self._resolve_host(host, port, traces=traces)
            ^^^^^^^^^^^^^^^^^^^^^^^^^^^^^^^^^^^^^^^^^^^^^^^^^^^
  File "/home/fizr07/Desktop/progProjects/bots/CISbot/botenv/lib/python3.12/site-packages/aiohttp/connector.py", line 971, in _resolve_host
    return await asyncio.shield(resolved_host_task)
           ^^^^^^^^^^^^^^^^^^^^^^^^^^^^^^^^^^^^^^^^
  File "/home/fizr07/Desktop/progProjects/bots/CISbot/botenv/lib/python3.12/site-packages/aiohttp/connector.py", line 1002, in _resolve_host_with_throttle
    addrs = await self._resolver.resolve(host, port, family=self._family)
            ^^^^^^^^^^^^^^^^^^^^^^^^^^^^^^^^^^^^^^^^^^^^^^^^^^^^^^^^^^^^^
  File "/home/fizr07/Desktop/progProjects/bots/CISbot/botenv/lib/python3.12/site-packages/aiohttp/resolver.py", line 38, in resolve
    infos = await self._loop.getaddrinfo(
            ^^^^^^^^^^^^^^^^^^^^^^^^^^^^^
  File "/usr/lib/python3.12/asyncio/base_events.py", line 901, in getaddrinfo
    return await self.run_in_executor(
           ^^^^^^^^^^^^^^^^^^^^^^^^^^^
  File "/usr/lib/python3.12/concurrent/futures/thread.py", line 58, in run
    result = self.fn(*self.args, **self.kwargs)
             ^^^^^^^^^^^^^^^^^^^^^^^^^^^^^^^^^^
  File "/usr/lib/python3.12/socket.py", line 976, in getaddrinfo
    for res in _socket.getaddrinfo(host, port, family, type, proto, flags):
               ^^^^^^^^^^^^^^^^^^^^^^^^^^^^^^^^^^^^^^^^^^^^^^^^^^^^^^^^^^^
socket.gaierror: [Errno -2] Name or service not known

The above exception was the direct cause of the following exception:

Traceback (most recent call last):
  File "/home/fizr07/Desktop/progProjects/bots/CISbot/botenv/lib/python3.12/site-packages/discord/client.py", line 664, in connect
    self.ws = await asyncio.wait_for(coro, timeout=60.0)
              ^^^^^^^^^^^^^^^^^^^^^^^^^^^^^^^^^^^^^^^^^^
  File "/usr/lib/python3.12/asyncio/tasks.py", line 520, in wait_for
    return await fut
           ^^^^^^^^^
  File "/home/fizr07/Desktop/progProjects/bots/CISbot/botenv/lib/python3.12/site-packages/discord/gateway.py", line 374, in from_client
    socket = await client.http.ws_connect(str(url))
             ^^^^^^^^^^^^^^^^^^^^^^^^^^^^^^^^^^^^^^
  File "/home/fizr07/Desktop/progProjects/bots/CISbot/botenv/lib/python3.12/site-packages/discord/http.py", line 550, in ws_connect
    return await self.__session.ws_connect(url, **kwargs)
           ^^^^^^^^^^^^^^^^^^^^^^^^^^^^^^^^^^^^^^^^^^^^^^
  File "/home/fizr07/Desktop/progProjects/bots/CISbot/botenv/lib/python3.12/site-packages/aiohttp/client.py", line 937, in _ws_connect
    resp = await self.request(
           ^^^^^^^^^^^^^^^^^^^
  File "/home/fizr07/Desktop/progProjects/bots/CISbot/botenv/lib/python3.12/site-packages/aiohttp/client.py", line 663, in _request
    conn = await self._connector.connect(
           ^^^^^^^^^^^^^^^^^^^^^^^^^^^^^^
  File "/home/fizr07/Desktop/progProjects/bots/CISbot/botenv/lib/python3.12/site-packages/aiohttp/connector.py", line 563, in connect
    proto = await self._create_connection(req, traces, timeout)
            ^^^^^^^^^^^^^^^^^^^^^^^^^^^^^^^^^^^^^^^^^^^^^^^^^^^
  File "/home/fizr07/Desktop/progProjects/bots/CISbot/botenv/lib/python3.12/site-packages/aiohttp/connector.py", line 1032, in _create_connection
    _, proto = await self._create_direct_connection(req, traces, timeout)
               ^^^^^^^^^^^^^^^^^^^^^^^^^^^^^^^^^^^^^^^^^^^^^^^^^^^^^^^^^^
  File "/home/fizr07/Desktop/progProjects/bots/CISbot/botenv/lib/python3.12/site-packages/aiohttp/connector.py", line 1323, in _create_direct_connection
    raise ClientConnectorDNSError(req.connection_key, exc) from exc
aiohttp.client_exceptions.ClientConnectorDNSError: Cannot connect to host gateway-us-east1-c.discord.gg:443 ssl:default [Name or service not known]
[2024-10-26 21:52:03] [ERROR   ] discord.client: Attempting a reconnect in 36.70s
Traceback (most recent call last):
  File "/home/fizr07/Desktop/progProjects/bots/CISbot/botenv/lib/python3.12/site-packages/aiohttp/connector.py", line 1317, in _create_direct_connection
    hosts = await self._resolve_host(host, port, traces=traces)
            ^^^^^^^^^^^^^^^^^^^^^^^^^^^^^^^^^^^^^^^^^^^^^^^^^^^
  File "/home/fizr07/Desktop/progProjects/bots/CISbot/botenv/lib/python3.12/site-packages/aiohttp/connector.py", line 971, in _resolve_host
    return await asyncio.shield(resolved_host_task)
           ^^^^^^^^^^^^^^^^^^^^^^^^^^^^^^^^^^^^^^^^
  File "/home/fizr07/Desktop/progProjects/bots/CISbot/botenv/lib/python3.12/site-packages/aiohttp/connector.py", line 1002, in _resolve_host_with_throttle
    addrs = await self._resolver.resolve(host, port, family=self._family)
            ^^^^^^^^^^^^^^^^^^^^^^^^^^^^^^^^^^^^^^^^^^^^^^^^^^^^^^^^^^^^^
  File "/home/fizr07/Desktop/progProjects/bots/CISbot/botenv/lib/python3.12/site-packages/aiohttp/resolver.py", line 38, in resolve
    infos = await self._loop.getaddrinfo(
            ^^^^^^^^^^^^^^^^^^^^^^^^^^^^^
  File "/usr/lib/python3.12/asyncio/base_events.py", line 901, in getaddrinfo
    return await self.run_in_executor(
           ^^^^^^^^^^^^^^^^^^^^^^^^^^^
  File "/usr/lib/python3.12/concurrent/futures/thread.py", line 58, in run
    result = self.fn(*self.args, **self.kwargs)
             ^^^^^^^^^^^^^^^^^^^^^^^^^^^^^^^^^^
  File "/usr/lib/python3.12/socket.py", line 976, in getaddrinfo
    for res in _socket.getaddrinfo(host, port, family, type, proto, flags):
               ^^^^^^^^^^^^^^^^^^^^^^^^^^^^^^^^^^^^^^^^^^^^^^^^^^^^^^^^^^^
socket.gaierror: [Errno -2] Name or service not known

The above exception was the direct cause of the following exception:

Traceback (most recent call last):
  File "/home/fizr07/Desktop/progProjects/bots/CISbot/botenv/lib/python3.12/site-packages/discord/client.py", line 664, in connect
    self.ws = await asyncio.wait_for(coro, timeout=60.0)
              ^^^^^^^^^^^^^^^^^^^^^^^^^^^^^^^^^^^^^^^^^^
  File "/usr/lib/python3.12/asyncio/tasks.py", line 520, in wait_for
    return await fut
           ^^^^^^^^^
  File "/home/fizr07/Desktop/progProjects/bots/CISbot/botenv/lib/python3.12/site-packages/discord/gateway.py", line 374, in from_client
    socket = await client.http.ws_connect(str(url))
             ^^^^^^^^^^^^^^^^^^^^^^^^^^^^^^^^^^^^^^
  File "/home/fizr07/Desktop/progProjects/bots/CISbot/botenv/lib/python3.12/site-packages/discord/http.py", line 550, in ws_connect
    return await self.__session.ws_connect(url, **kwargs)
           ^^^^^^^^^^^^^^^^^^^^^^^^^^^^^^^^^^^^^^^^^^^^^^
  File "/home/fizr07/Desktop/progProjects/bots/CISbot/botenv/lib/python3.12/site-packages/aiohttp/client.py", line 937, in _ws_connect
    resp = await self.request(
           ^^^^^^^^^^^^^^^^^^^
  File "/home/fizr07/Desktop/progProjects/bots/CISbot/botenv/lib/python3.12/site-packages/aiohttp/client.py", line 663, in _request
    conn = await self._connector.connect(
           ^^^^^^^^^^^^^^^^^^^^^^^^^^^^^^
  File "/home/fizr07/Desktop/progProjects/bots/CISbot/botenv/lib/python3.12/site-packages/aiohttp/connector.py", line 563, in connect
    proto = await self._create_connection(req, traces, timeout)
            ^^^^^^^^^^^^^^^^^^^^^^^^^^^^^^^^^^^^^^^^^^^^^^^^^^^
  File "/home/fizr07/Desktop/progProjects/bots/CISbot/botenv/lib/python3.12/site-packages/aiohttp/connector.py", line 1032, in _create_connection
    _, proto = await self._create_direct_connection(req, traces, timeout)
               ^^^^^^^^^^^^^^^^^^^^^^^^^^^^^^^^^^^^^^^^^^^^^^^^^^^^^^^^^^
  File "/home/fizr07/Desktop/progProjects/bots/CISbot/botenv/lib/python3.12/site-packages/aiohttp/connector.py", line 1323, in _create_direct_connection
    raise ClientConnectorDNSError(req.connection_key, exc) from exc
aiohttp.client_exceptions.ClientConnectorDNSError: Cannot connect to host gateway-us-east1-c.discord.gg:443 ssl:default [Name or service not known]
[2024-10-26 21:52:41] [INFO    ] discord.gateway: Shard ID None session has been invalidated.
[2024-10-26 21:52:46] [INFO    ] discord.gateway: Shard ID None has connected to Gateway (Session ID: 84c61d95d85e8ec581ccda1ae3e2e1ac).
[2024-10-26 23:50:07] [INFO    ] discord.gateway: Shard ID None has successfully RESUMED session 84c61d95d85e8ec581ccda1ae3e2e1ac.
[2024-10-27 02:43:00] [INFO    ] discord.gateway: Shard ID None has successfully RESUMED session 84c61d95d85e8ec581ccda1ae3e2e1ac.
[2024-10-27 03:05:48] [INFO    ] discord.gateway: Shard ID None has successfully RESUMED session 84c61d95d85e8ec581ccda1ae3e2e1ac.
[2024-10-27 06:15:34] [INFO    ] discord.gateway: Shard ID None has successfully RESUMED session 84c61d95d85e8ec581ccda1ae3e2e1ac.
[2024-10-27 06:33:53] [INFO    ] discord.gateway: Shard ID None has successfully RESUMED session 84c61d95d85e8ec581ccda1ae3e2e1ac.
[2024-10-27 09:51:09] [INFO    ] discord.gateway: Shard ID None has successfully RESUMED session 84c61d95d85e8ec581ccda1ae3e2e1ac.
[2024-10-27 11:12:48] [INFO    ] discord.gateway: Shard ID None has successfully RESUMED session 84c61d95d85e8ec581ccda1ae3e2e1ac.
[2024-10-27 14:17:16] [INFO    ] discord.gateway: Shard ID None has successfully RESUMED session 84c61d95d85e8ec581ccda1ae3e2e1ac.
[2024-10-27 17:22:48] [INFO    ] discord.gateway: Shard ID None has successfully RESUMED session 84c61d95d85e8ec581ccda1ae3e2e1ac.
[main 5366c60] Add questions
 1 file changed, 5 insertions(+)
fatal: could not read Username for 'https://github.com': No such device or address
[2024-10-27 20:14:12] [INFO    ] discord.gateway: Shard ID None has successfully RESUMED session 84c61d95d85e8ec581ccda1ae3e2e1ac.
[2024-10-27 22:21:24] [INFO    ] discord.gateway: Shard ID None has successfully RESUMED session 84c61d95d85e8ec581ccda1ae3e2e1ac.
[2024-10-27 23:50:38] [INFO    ] discord.gateway: Shard ID None has successfully RESUMED session 84c61d95d85e8ec581ccda1ae3e2e1ac.
[main bba1831] Add questions
 1 file changed, 4 insertions(+)
fatal: could not read Username for 'https://github.com': No such device or address
[2024-10-28 02:53:23] [INFO    ] discord.gateway: Shard ID None has successfully RESUMED session 84c61d95d85e8ec581ccda1ae3e2e1ac.
[2024-10-28 03:24:49] [INFO    ] discord.gateway: Shard ID None has successfully RESUMED session 84c61d95d85e8ec581ccda1ae3e2e1ac.
[2024-10-28 05:38:12] [INFO    ] discord.gateway: Shard ID None has successfully RESUMED session 84c61d95d85e8ec581ccda1ae3e2e1ac.
[2024-10-28 06:21:14] [INFO    ] discord.gateway: Shard ID None has successfully RESUMED session 84c61d95d85e8ec581ccda1ae3e2e1ac.
[2024-10-28 08:16:40] [INFO    ] discord.gateway: Shard ID None has successfully RESUMED session 84c61d95d85e8ec581ccda1ae3e2e1ac.
[2024-10-28 09:33:18] [ERROR   ] discord.client: Attempting a reconnect in 1.34s
Traceback (most recent call last):
  File "/home/fizr07/Desktop/progProjects/bots/CISbot/botenv/lib/python3.12/site-packages/aiohttp/connector.py", line 1317, in _create_direct_connection
    hosts = await self._resolve_host(host, port, traces=traces)
            ^^^^^^^^^^^^^^^^^^^^^^^^^^^^^^^^^^^^^^^^^^^^^^^^^^^
  File "/home/fizr07/Desktop/progProjects/bots/CISbot/botenv/lib/python3.12/site-packages/aiohttp/connector.py", line 971, in _resolve_host
    return await asyncio.shield(resolved_host_task)
           ^^^^^^^^^^^^^^^^^^^^^^^^^^^^^^^^^^^^^^^^
  File "/home/fizr07/Desktop/progProjects/bots/CISbot/botenv/lib/python3.12/site-packages/aiohttp/connector.py", line 1002, in _resolve_host_with_throttle
    addrs = await self._resolver.resolve(host, port, family=self._family)
            ^^^^^^^^^^^^^^^^^^^^^^^^^^^^^^^^^^^^^^^^^^^^^^^^^^^^^^^^^^^^^
  File "/home/fizr07/Desktop/progProjects/bots/CISbot/botenv/lib/python3.12/site-packages/aiohttp/resolver.py", line 38, in resolve
    infos = await self._loop.getaddrinfo(
            ^^^^^^^^^^^^^^^^^^^^^^^^^^^^^
  File "/usr/lib/python3.12/asyncio/base_events.py", line 901, in getaddrinfo
    return await self.run_in_executor(
           ^^^^^^^^^^^^^^^^^^^^^^^^^^^
  File "/usr/lib/python3.12/concurrent/futures/thread.py", line 58, in run
    result = self.fn(*self.args, **self.kwargs)
             ^^^^^^^^^^^^^^^^^^^^^^^^^^^^^^^^^^
  File "/usr/lib/python3.12/socket.py", line 976, in getaddrinfo
    for res in _socket.getaddrinfo(host, port, family, type, proto, flags):
               ^^^^^^^^^^^^^^^^^^^^^^^^^^^^^^^^^^^^^^^^^^^^^^^^^^^^^^^^^^^
socket.gaierror: [Errno -2] Name or service not known

The above exception was the direct cause of the following exception:

Traceback (most recent call last):
  File "/home/fizr07/Desktop/progProjects/bots/CISbot/botenv/lib/python3.12/site-packages/discord/client.py", line 664, in connect
    self.ws = await asyncio.wait_for(coro, timeout=60.0)
              ^^^^^^^^^^^^^^^^^^^^^^^^^^^^^^^^^^^^^^^^^^
  File "/usr/lib/python3.12/asyncio/tasks.py", line 520, in wait_for
    return await fut
           ^^^^^^^^^
  File "/home/fizr07/Desktop/progProjects/bots/CISbot/botenv/lib/python3.12/site-packages/discord/gateway.py", line 374, in from_client
    socket = await client.http.ws_connect(str(url))
             ^^^^^^^^^^^^^^^^^^^^^^^^^^^^^^^^^^^^^^
  File "/home/fizr07/Desktop/progProjects/bots/CISbot/botenv/lib/python3.12/site-packages/discord/http.py", line 550, in ws_connect
    return await self.__session.ws_connect(url, **kwargs)
           ^^^^^^^^^^^^^^^^^^^^^^^^^^^^^^^^^^^^^^^^^^^^^^
  File "/home/fizr07/Desktop/progProjects/bots/CISbot/botenv/lib/python3.12/site-packages/aiohttp/client.py", line 937, in _ws_connect
    resp = await self.request(
           ^^^^^^^^^^^^^^^^^^^
  File "/home/fizr07/Desktop/progProjects/bots/CISbot/botenv/lib/python3.12/site-packages/aiohttp/client.py", line 663, in _request
    conn = await self._connector.connect(
           ^^^^^^^^^^^^^^^^^^^^^^^^^^^^^^
  File "/home/fizr07/Desktop/progProjects/bots/CISbot/botenv/lib/python3.12/site-packages/aiohttp/connector.py", line 563, in connect
    proto = await self._create_connection(req, traces, timeout)
            ^^^^^^^^^^^^^^^^^^^^^^^^^^^^^^^^^^^^^^^^^^^^^^^^^^^
  File "/home/fizr07/Desktop/progProjects/bots/CISbot/botenv/lib/python3.12/site-packages/aiohttp/connector.py", line 1032, in _create_connection
    _, proto = await self._create_direct_connection(req, traces, timeout)
               ^^^^^^^^^^^^^^^^^^^^^^^^^^^^^^^^^^^^^^^^^^^^^^^^^^^^^^^^^^
  File "/home/fizr07/Desktop/progProjects/bots/CISbot/botenv/lib/python3.12/site-packages/aiohttp/connector.py", line 1323, in _create_direct_connection
    raise ClientConnectorDNSError(req.connection_key, exc) from exc
aiohttp.client_exceptions.ClientConnectorDNSError: Cannot connect to host gateway-us-east1-c.discord.gg:443 ssl:default [Name or service not known]
[2024-10-28 09:33:19] [ERROR   ] discord.client: Attempting a reconnect in 3.24s
Traceback (most recent call last):
  File "/home/fizr07/Desktop/progProjects/bots/CISbot/botenv/lib/python3.12/site-packages/aiohttp/connector.py", line 1317, in _create_direct_connection
    hosts = await self._resolve_host(host, port, traces=traces)
            ^^^^^^^^^^^^^^^^^^^^^^^^^^^^^^^^^^^^^^^^^^^^^^^^^^^
  File "/home/fizr07/Desktop/progProjects/bots/CISbot/botenv/lib/python3.12/site-packages/aiohttp/connector.py", line 971, in _resolve_host
    return await asyncio.shield(resolved_host_task)
           ^^^^^^^^^^^^^^^^^^^^^^^^^^^^^^^^^^^^^^^^
  File "/home/fizr07/Desktop/progProjects/bots/CISbot/botenv/lib/python3.12/site-packages/aiohttp/connector.py", line 1002, in _resolve_host_with_throttle
    addrs = await self._resolver.resolve(host, port, family=self._family)
            ^^^^^^^^^^^^^^^^^^^^^^^^^^^^^^^^^^^^^^^^^^^^^^^^^^^^^^^^^^^^^
  File "/home/fizr07/Desktop/progProjects/bots/CISbot/botenv/lib/python3.12/site-packages/aiohttp/resolver.py", line 38, in resolve
    infos = await self._loop.getaddrinfo(
            ^^^^^^^^^^^^^^^^^^^^^^^^^^^^^
  File "/usr/lib/python3.12/asyncio/base_events.py", line 901, in getaddrinfo
    return await self.run_in_executor(
           ^^^^^^^^^^^^^^^^^^^^^^^^^^^
  File "/usr/lib/python3.12/concurrent/futures/thread.py", line 58, in run
    result = self.fn(*self.args, **self.kwargs)
             ^^^^^^^^^^^^^^^^^^^^^^^^^^^^^^^^^^
  File "/usr/lib/python3.12/socket.py", line 976, in getaddrinfo
    for res in _socket.getaddrinfo(host, port, family, type, proto, flags):
               ^^^^^^^^^^^^^^^^^^^^^^^^^^^^^^^^^^^^^^^^^^^^^^^^^^^^^^^^^^^
socket.gaierror: [Errno -2] Name or service not known

The above exception was the direct cause of the following exception:

Traceback (most recent call last):
  File "/home/fizr07/Desktop/progProjects/bots/CISbot/botenv/lib/python3.12/site-packages/discord/client.py", line 664, in connect
    self.ws = await asyncio.wait_for(coro, timeout=60.0)
              ^^^^^^^^^^^^^^^^^^^^^^^^^^^^^^^^^^^^^^^^^^
  File "/usr/lib/python3.12/asyncio/tasks.py", line 520, in wait_for
    return await fut
           ^^^^^^^^^
  File "/home/fizr07/Desktop/progProjects/bots/CISbot/botenv/lib/python3.12/site-packages/discord/gateway.py", line 374, in from_client
    socket = await client.http.ws_connect(str(url))
             ^^^^^^^^^^^^^^^^^^^^^^^^^^^^^^^^^^^^^^
  File "/home/fizr07/Desktop/progProjects/bots/CISbot/botenv/lib/python3.12/site-packages/discord/http.py", line 550, in ws_connect
    return await self.__session.ws_connect(url, **kwargs)
           ^^^^^^^^^^^^^^^^^^^^^^^^^^^^^^^^^^^^^^^^^^^^^^
  File "/home/fizr07/Desktop/progProjects/bots/CISbot/botenv/lib/python3.12/site-packages/aiohttp/client.py", line 937, in _ws_connect
    resp = await self.request(
           ^^^^^^^^^^^^^^^^^^^
  File "/home/fizr07/Desktop/progProjects/bots/CISbot/botenv/lib/python3.12/site-packages/aiohttp/client.py", line 663, in _request
    conn = await self._connector.connect(
           ^^^^^^^^^^^^^^^^^^^^^^^^^^^^^^
  File "/home/fizr07/Desktop/progProjects/bots/CISbot/botenv/lib/python3.12/site-packages/aiohttp/connector.py", line 563, in connect
    proto = await self._create_connection(req, traces, timeout)
            ^^^^^^^^^^^^^^^^^^^^^^^^^^^^^^^^^^^^^^^^^^^^^^^^^^^
  File "/home/fizr07/Desktop/progProjects/bots/CISbot/botenv/lib/python3.12/site-packages/aiohttp/connector.py", line 1032, in _create_connection
    _, proto = await self._create_direct_connection(req, traces, timeout)
               ^^^^^^^^^^^^^^^^^^^^^^^^^^^^^^^^^^^^^^^^^^^^^^^^^^^^^^^^^^
  File "/home/fizr07/Desktop/progProjects/bots/CISbot/botenv/lib/python3.12/site-packages/aiohttp/connector.py", line 1323, in _create_direct_connection
    raise ClientConnectorDNSError(req.connection_key, exc) from exc
aiohttp.client_exceptions.ClientConnectorDNSError: Cannot connect to host gateway-us-east1-c.discord.gg:443 ssl:default [Name or service not known]
[2024-10-28 09:33:22] [ERROR   ] discord.client: Attempting a reconnect in 2.61s
Traceback (most recent call last):
  File "/home/fizr07/Desktop/progProjects/bots/CISbot/botenv/lib/python3.12/site-packages/aiohttp/connector.py", line 1317, in _create_direct_connection
    hosts = await self._resolve_host(host, port, traces=traces)
            ^^^^^^^^^^^^^^^^^^^^^^^^^^^^^^^^^^^^^^^^^^^^^^^^^^^
  File "/home/fizr07/Desktop/progProjects/bots/CISbot/botenv/lib/python3.12/site-packages/aiohttp/connector.py", line 971, in _resolve_host
    return await asyncio.shield(resolved_host_task)
           ^^^^^^^^^^^^^^^^^^^^^^^^^^^^^^^^^^^^^^^^
  File "/home/fizr07/Desktop/progProjects/bots/CISbot/botenv/lib/python3.12/site-packages/aiohttp/connector.py", line 1002, in _resolve_host_with_throttle
    addrs = await self._resolver.resolve(host, port, family=self._family)
            ^^^^^^^^^^^^^^^^^^^^^^^^^^^^^^^^^^^^^^^^^^^^^^^^^^^^^^^^^^^^^
  File "/home/fizr07/Desktop/progProjects/bots/CISbot/botenv/lib/python3.12/site-packages/aiohttp/resolver.py", line 38, in resolve
    infos = await self._loop.getaddrinfo(
            ^^^^^^^^^^^^^^^^^^^^^^^^^^^^^
  File "/usr/lib/python3.12/asyncio/base_events.py", line 901, in getaddrinfo
    return await self.run_in_executor(
           ^^^^^^^^^^^^^^^^^^^^^^^^^^^
  File "/usr/lib/python3.12/concurrent/futures/thread.py", line 58, in run
    result = self.fn(*self.args, **self.kwargs)
             ^^^^^^^^^^^^^^^^^^^^^^^^^^^^^^^^^^
  File "/usr/lib/python3.12/socket.py", line 976, in getaddrinfo
    for res in _socket.getaddrinfo(host, port, family, type, proto, flags):
               ^^^^^^^^^^^^^^^^^^^^^^^^^^^^^^^^^^^^^^^^^^^^^^^^^^^^^^^^^^^
socket.gaierror: [Errno -2] Name or service not known

The above exception was the direct cause of the following exception:

Traceback (most recent call last):
  File "/home/fizr07/Desktop/progProjects/bots/CISbot/botenv/lib/python3.12/site-packages/discord/client.py", line 664, in connect
    self.ws = await asyncio.wait_for(coro, timeout=60.0)
              ^^^^^^^^^^^^^^^^^^^^^^^^^^^^^^^^^^^^^^^^^^
  File "/usr/lib/python3.12/asyncio/tasks.py", line 520, in wait_for
    return await fut
           ^^^^^^^^^
  File "/home/fizr07/Desktop/progProjects/bots/CISbot/botenv/lib/python3.12/site-packages/discord/gateway.py", line 374, in from_client
    socket = await client.http.ws_connect(str(url))
             ^^^^^^^^^^^^^^^^^^^^^^^^^^^^^^^^^^^^^^
  File "/home/fizr07/Desktop/progProjects/bots/CISbot/botenv/lib/python3.12/site-packages/discord/http.py", line 550, in ws_connect
    return await self.__session.ws_connect(url, **kwargs)
           ^^^^^^^^^^^^^^^^^^^^^^^^^^^^^^^^^^^^^^^^^^^^^^
  File "/home/fizr07/Desktop/progProjects/bots/CISbot/botenv/lib/python3.12/site-packages/aiohttp/client.py", line 937, in _ws_connect
    resp = await self.request(
           ^^^^^^^^^^^^^^^^^^^
  File "/home/fizr07/Desktop/progProjects/bots/CISbot/botenv/lib/python3.12/site-packages/aiohttp/client.py", line 663, in _request
    conn = await self._connector.connect(
           ^^^^^^^^^^^^^^^^^^^^^^^^^^^^^^
  File "/home/fizr07/Desktop/progProjects/bots/CISbot/botenv/lib/python3.12/site-packages/aiohttp/connector.py", line 563, in connect
    proto = await self._create_connection(req, traces, timeout)
            ^^^^^^^^^^^^^^^^^^^^^^^^^^^^^^^^^^^^^^^^^^^^^^^^^^^
  File "/home/fizr07/Desktop/progProjects/bots/CISbot/botenv/lib/python3.12/site-packages/aiohttp/connector.py", line 1032, in _create_connection
    _, proto = await self._create_direct_connection(req, traces, timeout)
               ^^^^^^^^^^^^^^^^^^^^^^^^^^^^^^^^^^^^^^^^^^^^^^^^^^^^^^^^^^
  File "/home/fizr07/Desktop/progProjects/bots/CISbot/botenv/lib/python3.12/site-packages/aiohttp/connector.py", line 1323, in _create_direct_connection
    raise ClientConnectorDNSError(req.connection_key, exc) from exc
aiohttp.client_exceptions.ClientConnectorDNSError: Cannot connect to host gateway-us-east1-c.discord.gg:443 ssl:default [Name or service not known]
[2024-10-28 09:33:25] [ERROR   ] discord.client: Attempting a reconnect in 12.30s
Traceback (most recent call last):
  File "/home/fizr07/Desktop/progProjects/bots/CISbot/botenv/lib/python3.12/site-packages/aiohttp/connector.py", line 1317, in _create_direct_connection
    hosts = await self._resolve_host(host, port, traces=traces)
            ^^^^^^^^^^^^^^^^^^^^^^^^^^^^^^^^^^^^^^^^^^^^^^^^^^^
  File "/home/fizr07/Desktop/progProjects/bots/CISbot/botenv/lib/python3.12/site-packages/aiohttp/connector.py", line 971, in _resolve_host
    return await asyncio.shield(resolved_host_task)
           ^^^^^^^^^^^^^^^^^^^^^^^^^^^^^^^^^^^^^^^^
  File "/home/fizr07/Desktop/progProjects/bots/CISbot/botenv/lib/python3.12/site-packages/aiohttp/connector.py", line 1002, in _resolve_host_with_throttle
    addrs = await self._resolver.resolve(host, port, family=self._family)
            ^^^^^^^^^^^^^^^^^^^^^^^^^^^^^^^^^^^^^^^^^^^^^^^^^^^^^^^^^^^^^
  File "/home/fizr07/Desktop/progProjects/bots/CISbot/botenv/lib/python3.12/site-packages/aiohttp/resolver.py", line 38, in resolve
    infos = await self._loop.getaddrinfo(
            ^^^^^^^^^^^^^^^^^^^^^^^^^^^^^
  File "/usr/lib/python3.12/asyncio/base_events.py", line 901, in getaddrinfo
    return await self.run_in_executor(
           ^^^^^^^^^^^^^^^^^^^^^^^^^^^
  File "/usr/lib/python3.12/concurrent/futures/thread.py", line 58, in run
    result = self.fn(*self.args, **self.kwargs)
             ^^^^^^^^^^^^^^^^^^^^^^^^^^^^^^^^^^
  File "/usr/lib/python3.12/socket.py", line 976, in getaddrinfo
    for res in _socket.getaddrinfo(host, port, family, type, proto, flags):
               ^^^^^^^^^^^^^^^^^^^^^^^^^^^^^^^^^^^^^^^^^^^^^^^^^^^^^^^^^^^
socket.gaierror: [Errno -2] Name or service not known

The above exception was the direct cause of the following exception:

Traceback (most recent call last):
  File "/home/fizr07/Desktop/progProjects/bots/CISbot/botenv/lib/python3.12/site-packages/discord/client.py", line 664, in connect
    self.ws = await asyncio.wait_for(coro, timeout=60.0)
              ^^^^^^^^^^^^^^^^^^^^^^^^^^^^^^^^^^^^^^^^^^
  File "/usr/lib/python3.12/asyncio/tasks.py", line 520, in wait_for
    return await fut
           ^^^^^^^^^
  File "/home/fizr07/Desktop/progProjects/bots/CISbot/botenv/lib/python3.12/site-packages/discord/gateway.py", line 374, in from_client
    socket = await client.http.ws_connect(str(url))
             ^^^^^^^^^^^^^^^^^^^^^^^^^^^^^^^^^^^^^^
  File "/home/fizr07/Desktop/progProjects/bots/CISbot/botenv/lib/python3.12/site-packages/discord/http.py", line 550, in ws_connect
    return await self.__session.ws_connect(url, **kwargs)
           ^^^^^^^^^^^^^^^^^^^^^^^^^^^^^^^^^^^^^^^^^^^^^^
  File "/home/fizr07/Desktop/progProjects/bots/CISbot/botenv/lib/python3.12/site-packages/aiohttp/client.py", line 937, in _ws_connect
    resp = await self.request(
           ^^^^^^^^^^^^^^^^^^^
  File "/home/fizr07/Desktop/progProjects/bots/CISbot/botenv/lib/python3.12/site-packages/aiohttp/client.py", line 663, in _request
    conn = await self._connector.connect(
           ^^^^^^^^^^^^^^^^^^^^^^^^^^^^^^
  File "/home/fizr07/Desktop/progProjects/bots/CISbot/botenv/lib/python3.12/site-packages/aiohttp/connector.py", line 563, in connect
    proto = await self._create_connection(req, traces, timeout)
            ^^^^^^^^^^^^^^^^^^^^^^^^^^^^^^^^^^^^^^^^^^^^^^^^^^^
  File "/home/fizr07/Desktop/progProjects/bots/CISbot/botenv/lib/python3.12/site-packages/aiohttp/connector.py", line 1032, in _create_connection
    _, proto = await self._create_direct_connection(req, traces, timeout)
               ^^^^^^^^^^^^^^^^^^^^^^^^^^^^^^^^^^^^^^^^^^^^^^^^^^^^^^^^^^
  File "/home/fizr07/Desktop/progProjects/bots/CISbot/botenv/lib/python3.12/site-packages/aiohttp/connector.py", line 1323, in _create_direct_connection
    raise ClientConnectorDNSError(req.connection_key, exc) from exc
aiohttp.client_exceptions.ClientConnectorDNSError: Cannot connect to host gateway-us-east1-c.discord.gg:443 ssl:default [Name or service not known]
[2024-10-28 09:33:37] [ERROR   ] discord.client: Attempting a reconnect in 2.50s
Traceback (most recent call last):
  File "/home/fizr07/Desktop/progProjects/bots/CISbot/botenv/lib/python3.12/site-packages/aiohttp/connector.py", line 1317, in _create_direct_connection
    hosts = await self._resolve_host(host, port, traces=traces)
            ^^^^^^^^^^^^^^^^^^^^^^^^^^^^^^^^^^^^^^^^^^^^^^^^^^^
  File "/home/fizr07/Desktop/progProjects/bots/CISbot/botenv/lib/python3.12/site-packages/aiohttp/connector.py", line 971, in _resolve_host
    return await asyncio.shield(resolved_host_task)
           ^^^^^^^^^^^^^^^^^^^^^^^^^^^^^^^^^^^^^^^^
  File "/home/fizr07/Desktop/progProjects/bots/CISbot/botenv/lib/python3.12/site-packages/aiohttp/connector.py", line 1002, in _resolve_host_with_throttle
    addrs = await self._resolver.resolve(host, port, family=self._family)
            ^^^^^^^^^^^^^^^^^^^^^^^^^^^^^^^^^^^^^^^^^^^^^^^^^^^^^^^^^^^^^
  File "/home/fizr07/Desktop/progProjects/bots/CISbot/botenv/lib/python3.12/site-packages/aiohttp/resolver.py", line 38, in resolve
    infos = await self._loop.getaddrinfo(
            ^^^^^^^^^^^^^^^^^^^^^^^^^^^^^
  File "/usr/lib/python3.12/asyncio/base_events.py", line 901, in getaddrinfo
    return await self.run_in_executor(
           ^^^^^^^^^^^^^^^^^^^^^^^^^^^
  File "/usr/lib/python3.12/concurrent/futures/thread.py", line 58, in run
    result = self.fn(*self.args, **self.kwargs)
             ^^^^^^^^^^^^^^^^^^^^^^^^^^^^^^^^^^
  File "/usr/lib/python3.12/socket.py", line 976, in getaddrinfo
    for res in _socket.getaddrinfo(host, port, family, type, proto, flags):
               ^^^^^^^^^^^^^^^^^^^^^^^^^^^^^^^^^^^^^^^^^^^^^^^^^^^^^^^^^^^
socket.gaierror: [Errno -2] Name or service not known

The above exception was the direct cause of the following exception:

Traceback (most recent call last):
  File "/home/fizr07/Desktop/progProjects/bots/CISbot/botenv/lib/python3.12/site-packages/discord/client.py", line 664, in connect
    self.ws = await asyncio.wait_for(coro, timeout=60.0)
              ^^^^^^^^^^^^^^^^^^^^^^^^^^^^^^^^^^^^^^^^^^
  File "/usr/lib/python3.12/asyncio/tasks.py", line 520, in wait_for
    return await fut
           ^^^^^^^^^
  File "/home/fizr07/Desktop/progProjects/bots/CISbot/botenv/lib/python3.12/site-packages/discord/gateway.py", line 374, in from_client
    socket = await client.http.ws_connect(str(url))
             ^^^^^^^^^^^^^^^^^^^^^^^^^^^^^^^^^^^^^^
  File "/home/fizr07/Desktop/progProjects/bots/CISbot/botenv/lib/python3.12/site-packages/discord/http.py", line 550, in ws_connect
    return await self.__session.ws_connect(url, **kwargs)
           ^^^^^^^^^^^^^^^^^^^^^^^^^^^^^^^^^^^^^^^^^^^^^^
  File "/home/fizr07/Desktop/progProjects/bots/CISbot/botenv/lib/python3.12/site-packages/aiohttp/client.py", line 937, in _ws_connect
    resp = await self.request(
           ^^^^^^^^^^^^^^^^^^^
  File "/home/fizr07/Desktop/progProjects/bots/CISbot/botenv/lib/python3.12/site-packages/aiohttp/client.py", line 663, in _request
    conn = await self._connector.connect(
           ^^^^^^^^^^^^^^^^^^^^^^^^^^^^^^
  File "/home/fizr07/Desktop/progProjects/bots/CISbot/botenv/lib/python3.12/site-packages/aiohttp/connector.py", line 563, in connect
    proto = await self._create_connection(req, traces, timeout)
            ^^^^^^^^^^^^^^^^^^^^^^^^^^^^^^^^^^^^^^^^^^^^^^^^^^^
  File "/home/fizr07/Desktop/progProjects/bots/CISbot/botenv/lib/python3.12/site-packages/aiohttp/connector.py", line 1032, in _create_connection
    _, proto = await self._create_direct_connection(req, traces, timeout)
               ^^^^^^^^^^^^^^^^^^^^^^^^^^^^^^^^^^^^^^^^^^^^^^^^^^^^^^^^^^
  File "/home/fizr07/Desktop/progProjects/bots/CISbot/botenv/lib/python3.12/site-packages/aiohttp/connector.py", line 1323, in _create_direct_connection
    raise ClientConnectorDNSError(req.connection_key, exc) from exc
aiohttp.client_exceptions.ClientConnectorDNSError: Cannot connect to host gateway-us-east1-c.discord.gg:443 ssl:default [Name or service not known]
[2024-10-28 09:33:40] [ERROR   ] discord.client: Attempting a reconnect in 26.77s
Traceback (most recent call last):
  File "/home/fizr07/Desktop/progProjects/bots/CISbot/botenv/lib/python3.12/site-packages/aiohttp/connector.py", line 1317, in _create_direct_connection
    hosts = await self._resolve_host(host, port, traces=traces)
            ^^^^^^^^^^^^^^^^^^^^^^^^^^^^^^^^^^^^^^^^^^^^^^^^^^^
  File "/home/fizr07/Desktop/progProjects/bots/CISbot/botenv/lib/python3.12/site-packages/aiohttp/connector.py", line 971, in _resolve_host
    return await asyncio.shield(resolved_host_task)
           ^^^^^^^^^^^^^^^^^^^^^^^^^^^^^^^^^^^^^^^^
  File "/home/fizr07/Desktop/progProjects/bots/CISbot/botenv/lib/python3.12/site-packages/aiohttp/connector.py", line 1002, in _resolve_host_with_throttle
    addrs = await self._resolver.resolve(host, port, family=self._family)
            ^^^^^^^^^^^^^^^^^^^^^^^^^^^^^^^^^^^^^^^^^^^^^^^^^^^^^^^^^^^^^
  File "/home/fizr07/Desktop/progProjects/bots/CISbot/botenv/lib/python3.12/site-packages/aiohttp/resolver.py", line 38, in resolve
    infos = await self._loop.getaddrinfo(
            ^^^^^^^^^^^^^^^^^^^^^^^^^^^^^
  File "/usr/lib/python3.12/asyncio/base_events.py", line 901, in getaddrinfo
    return await self.run_in_executor(
           ^^^^^^^^^^^^^^^^^^^^^^^^^^^
  File "/usr/lib/python3.12/concurrent/futures/thread.py", line 58, in run
    result = self.fn(*self.args, **self.kwargs)
             ^^^^^^^^^^^^^^^^^^^^^^^^^^^^^^^^^^
  File "/usr/lib/python3.12/socket.py", line 976, in getaddrinfo
    for res in _socket.getaddrinfo(host, port, family, type, proto, flags):
               ^^^^^^^^^^^^^^^^^^^^^^^^^^^^^^^^^^^^^^^^^^^^^^^^^^^^^^^^^^^
socket.gaierror: [Errno -2] Name or service not known

The above exception was the direct cause of the following exception:

Traceback (most recent call last):
  File "/home/fizr07/Desktop/progProjects/bots/CISbot/botenv/lib/python3.12/site-packages/discord/client.py", line 664, in connect
    self.ws = await asyncio.wait_for(coro, timeout=60.0)
              ^^^^^^^^^^^^^^^^^^^^^^^^^^^^^^^^^^^^^^^^^^
  File "/usr/lib/python3.12/asyncio/tasks.py", line 520, in wait_for
    return await fut
           ^^^^^^^^^
  File "/home/fizr07/Desktop/progProjects/bots/CISbot/botenv/lib/python3.12/site-packages/discord/gateway.py", line 374, in from_client
    socket = await client.http.ws_connect(str(url))
             ^^^^^^^^^^^^^^^^^^^^^^^^^^^^^^^^^^^^^^
  File "/home/fizr07/Desktop/progProjects/bots/CISbot/botenv/lib/python3.12/site-packages/discord/http.py", line 550, in ws_connect
    return await self.__session.ws_connect(url, **kwargs)
           ^^^^^^^^^^^^^^^^^^^^^^^^^^^^^^^^^^^^^^^^^^^^^^
  File "/home/fizr07/Desktop/progProjects/bots/CISbot/botenv/lib/python3.12/site-packages/aiohttp/client.py", line 937, in _ws_connect
    resp = await self.request(
           ^^^^^^^^^^^^^^^^^^^
  File "/home/fizr07/Desktop/progProjects/bots/CISbot/botenv/lib/python3.12/site-packages/aiohttp/client.py", line 663, in _request
    conn = await self._connector.connect(
           ^^^^^^^^^^^^^^^^^^^^^^^^^^^^^^
  File "/home/fizr07/Desktop/progProjects/bots/CISbot/botenv/lib/python3.12/site-packages/aiohttp/connector.py", line 563, in connect
    proto = await self._create_connection(req, traces, timeout)
            ^^^^^^^^^^^^^^^^^^^^^^^^^^^^^^^^^^^^^^^^^^^^^^^^^^^
  File "/home/fizr07/Desktop/progProjects/bots/CISbot/botenv/lib/python3.12/site-packages/aiohttp/connector.py", line 1032, in _create_connection
    _, proto = await self._create_direct_connection(req, traces, timeout)
               ^^^^^^^^^^^^^^^^^^^^^^^^^^^^^^^^^^^^^^^^^^^^^^^^^^^^^^^^^^
  File "/home/fizr07/Desktop/progProjects/bots/CISbot/botenv/lib/python3.12/site-packages/aiohttp/connector.py", line 1323, in _create_direct_connection
    raise ClientConnectorDNSError(req.connection_key, exc) from exc
aiohttp.client_exceptions.ClientConnectorDNSError: Cannot connect to host gateway-us-east1-c.discord.gg:443 ssl:default [Name or service not known]
[2024-10-28 09:34:07] [ERROR   ] discord.client: Attempting a reconnect in 61.96s
Traceback (most recent call last):
  File "/home/fizr07/Desktop/progProjects/bots/CISbot/botenv/lib/python3.12/site-packages/aiohttp/connector.py", line 1317, in _create_direct_connection
    hosts = await self._resolve_host(host, port, traces=traces)
            ^^^^^^^^^^^^^^^^^^^^^^^^^^^^^^^^^^^^^^^^^^^^^^^^^^^
  File "/home/fizr07/Desktop/progProjects/bots/CISbot/botenv/lib/python3.12/site-packages/aiohttp/connector.py", line 971, in _resolve_host
    return await asyncio.shield(resolved_host_task)
           ^^^^^^^^^^^^^^^^^^^^^^^^^^^^^^^^^^^^^^^^
  File "/home/fizr07/Desktop/progProjects/bots/CISbot/botenv/lib/python3.12/site-packages/aiohttp/connector.py", line 1002, in _resolve_host_with_throttle
    addrs = await self._resolver.resolve(host, port, family=self._family)
            ^^^^^^^^^^^^^^^^^^^^^^^^^^^^^^^^^^^^^^^^^^^^^^^^^^^^^^^^^^^^^
  File "/home/fizr07/Desktop/progProjects/bots/CISbot/botenv/lib/python3.12/site-packages/aiohttp/resolver.py", line 38, in resolve
    infos = await self._loop.getaddrinfo(
            ^^^^^^^^^^^^^^^^^^^^^^^^^^^^^
  File "/usr/lib/python3.12/asyncio/base_events.py", line 901, in getaddrinfo
    return await self.run_in_executor(
           ^^^^^^^^^^^^^^^^^^^^^^^^^^^
  File "/usr/lib/python3.12/concurrent/futures/thread.py", line 58, in run
    result = self.fn(*self.args, **self.kwargs)
             ^^^^^^^^^^^^^^^^^^^^^^^^^^^^^^^^^^
  File "/usr/lib/python3.12/socket.py", line 976, in getaddrinfo
    for res in _socket.getaddrinfo(host, port, family, type, proto, flags):
               ^^^^^^^^^^^^^^^^^^^^^^^^^^^^^^^^^^^^^^^^^^^^^^^^^^^^^^^^^^^
socket.gaierror: [Errno -2] Name or service not known

The above exception was the direct cause of the following exception:

Traceback (most recent call last):
  File "/home/fizr07/Desktop/progProjects/bots/CISbot/botenv/lib/python3.12/site-packages/discord/client.py", line 664, in connect
    self.ws = await asyncio.wait_for(coro, timeout=60.0)
              ^^^^^^^^^^^^^^^^^^^^^^^^^^^^^^^^^^^^^^^^^^
  File "/usr/lib/python3.12/asyncio/tasks.py", line 520, in wait_for
    return await fut
           ^^^^^^^^^
  File "/home/fizr07/Desktop/progProjects/bots/CISbot/botenv/lib/python3.12/site-packages/discord/gateway.py", line 374, in from_client
    socket = await client.http.ws_connect(str(url))
             ^^^^^^^^^^^^^^^^^^^^^^^^^^^^^^^^^^^^^^
  File "/home/fizr07/Desktop/progProjects/bots/CISbot/botenv/lib/python3.12/site-packages/discord/http.py", line 550, in ws_connect
    return await self.__session.ws_connect(url, **kwargs)
           ^^^^^^^^^^^^^^^^^^^^^^^^^^^^^^^^^^^^^^^^^^^^^^
  File "/home/fizr07/Desktop/progProjects/bots/CISbot/botenv/lib/python3.12/site-packages/aiohttp/client.py", line 937, in _ws_connect
    resp = await self.request(
           ^^^^^^^^^^^^^^^^^^^
  File "/home/fizr07/Desktop/progProjects/bots/CISbot/botenv/lib/python3.12/site-packages/aiohttp/client.py", line 663, in _request
    conn = await self._connector.connect(
           ^^^^^^^^^^^^^^^^^^^^^^^^^^^^^^
  File "/home/fizr07/Desktop/progProjects/bots/CISbot/botenv/lib/python3.12/site-packages/aiohttp/connector.py", line 563, in connect
    proto = await self._create_connection(req, traces, timeout)
            ^^^^^^^^^^^^^^^^^^^^^^^^^^^^^^^^^^^^^^^^^^^^^^^^^^^
  File "/home/fizr07/Desktop/progProjects/bots/CISbot/botenv/lib/python3.12/site-packages/aiohttp/connector.py", line 1032, in _create_connection
    _, proto = await self._create_direct_connection(req, traces, timeout)
               ^^^^^^^^^^^^^^^^^^^^^^^^^^^^^^^^^^^^^^^^^^^^^^^^^^^^^^^^^^
  File "/home/fizr07/Desktop/progProjects/bots/CISbot/botenv/lib/python3.12/site-packages/aiohttp/connector.py", line 1323, in _create_direct_connection
    raise ClientConnectorDNSError(req.connection_key, exc) from exc
aiohttp.client_exceptions.ClientConnectorDNSError: Cannot connect to host gateway-us-east1-c.discord.gg:443 ssl:default [Name or service not known]
[2024-10-28 09:35:09] [INFO    ] discord.gateway: Shard ID None session has been invalidated.
[2024-10-28 09:35:15] [INFO    ] discord.gateway: Shard ID None has connected to Gateway (Session ID: 44423d71c6f3b81d65f26b29fb6aa68a).
